Workbook

Sheet ✏️ SME Input
B5: 📋 INSTRUCTIONS: Fill in ORANGE cells only. S.No = sequence number | VAST ID = your VAST system ID | APP ID = application code. Dropdown cells show ▼ — click to select. Leave rows blank if not used.
B6: IDENTIFIERS | E6: APPLICATION & WAVE | G6: DATABASE & OBJECT INVENTORY | Q6: ETL & REPORTING | T6: INFORMATICA & REPLICATION | X6: NOTES
B7: S.No | C7: VAST ID | D7: APP ID | E7: Application Name | F7: Wave / Release | G7: DB Size (GB) | H7: No. of Tables | I7: No. of Stored Procs | J7: No. of Views | K7: No. of Triggers | L7: SQL Agent Jobs | M7: Linked Servers | N7: CLR Objects | O7: SSIS Packages | P7: SSRS Reports | Q7: Informatica Workflows/Jobs (No workflow change — count) | R7: SSIS Complexity | S7: SSRS Strategy | T7: Informatica Job Count | U7: Replication Articles (Trans+Merge) | V7: Snapshot Publications | W7: Replication Type | X7: SME Notes / Risks
B8: ⬆ ENTER | C8: ⬆ ENTER | D8: ⬆ ENTER | E8: ⬆ ENTER | F8: ▼ Select | G8: ⬆ ENTER | H8: ⬆ ENTER | I8: ⬆ ENTER | J8: ⬆ ENTER | K8: ⬆ ENTER | L8: ⬆ ENTER | M8: ⬆ ENTER | N8: ⬆ ENTER | O8: ⬆ ENTER | P8: ⬆ ENTER | Q8: ⬆ ENTER | R8: ▼ Select | S8: ▼ Select | T8: ⬆ ENTER | U8: ⬆ ENTER | V8: ⬆ ENTER | W8: ▼ Select | X8: Free text
B38: TOTALS | G38: =SUM(G9:G37) -> 0 | H38: =SUM(H9:H37) -> 0 | I38: =SUM(I9:I37) -> 0 | J38: =SUM(J9:J37) -> 0 | K38: =SUM(K9:K37) -> 0 | L38: =SUM(L9:L37) -> 0 | M38: =SUM(M9:M37) -> 0 | N38: =SUM(N9:N37) -> 0 | ... Q38: =SUM(Q9:Q37) -> 0 | T38: =SUM(T9:T37) -> 0 | U38: =SUM(U9:U37) -> 0 | V38: =SUM(V9:V37) -> 0

Sheet 📋 App Effort Detail
B4: Formulas auto-calculate from SME Input sheet values. Orange = SME editable input. Green = calculated output. Hours = Days × 8. AI saving applied per role. Contingency = AI-adj × (1 + buffer%).
B5: APP IDENTITY | D5: DATABASE PROFILE | I5: SQL OBJECT INVENTORY | O5: ETL & REPORTING | R5: EFFORT TOTALS (hours) | AB5: INFORMATICA EFFORT (hrs) | AG5: ENVIRONMENT BREAKDOWN — Data & ETL (hrs) | AM5: TOTAL BY ENV (hrs) | AP5: APPLICATION IDENTIFIERS
B6: Application Name | C6: Tier (Auto) | D6: DB Size (GB) | E6: Tables | F6: Stored Procs | G6: Views | H6: Triggers | I6: SQL Agent Jobs | J6: Linked Servers | K6: CLR Objects | L6: SSIS Packages | M6: SSRS Reports | N6: Informatica Workflows/Jobs (No workflow change — count for JDBC) | O6: SSIS Complexity | P6: SSRS Strategy | Q6: Wave | R6: Gross Hours | S6: AI-Adj Hours | T6: Hours w/ Contingency | AB6: Informatica Job Count | AC6: Inform. Dev hrs | AD6: Inform. Test hrs | AE6: Inform. Prod hrs | AF6: Inform. Total hrs | AG6: Data Dev hrs | AH6: Data Test hrs | AI6: Data Prod hrs | AJ6: ETL Dev hrs | AK6: ETL Test hrs | AL6: ETL Prod hrs | AM6: Total Dev hrs | AN6: Total Test hrs | AO6: Total Prod hrs | AP6: S.No | AQ6: VAST ID | AR6: APP ID
B7: Label/Formula | C7: Label/Formula | D7: ⬆ Input | E7: ⬆ Input | F7: ⬆ Input | G7: ⬆ Input | H7: ⬆ Input | I7: ⬆ Input | J7: ⬆ Input | K7: ⬆ Input | L7: ⬆ Input | M7: ⬆ Input | N7: ⬆ Input | O7: ⬆ Input | P7: ⬆ Input | Q7: ⬆ Input | R7: Formula | S7: Formula | T7: Formula | AB7: Ref SME | AC7: Formula | AD7: Formula | AE7: Formula | AF7: Formula | AG7: Formula | AH7: Formula | AI7: Formula | AJ7: Formula | AK7: Formula | AL7: Formula | AM7: Formula | AN7: Formula | AO7: Formula | AP7: Ref SME | AQ7: Ref SME | AR7: Ref SME
B8: ='✏️ SME Input'!E9 -> 0 | C8: =IF(B8="","",IF(D8>1000,"T3 Complex",IF(D8>500,"T2 Moderate","T1 Simple"))) | D8: ='✏️ SME Input'!G9 -> 0 | E8: ='✏️ SME Input'!H9 -> 0 | F8: ='✏️ SME Input'!I9 -> 0 | G8: ='✏️ SME Input'!J9 -> 0 | H8: ='✏️ SME Input'!K9 -> 0 | I8: ='✏️ SME Input'!L9 -> 0 | J8: ='✏️ SME Input'!M9 -> 0 | K8: ='✏️ SME Input'!N9 -> 0 | ... P8: ='✏️ SME Input'!S9 -> 0 | Q8: ='✏️ SME Input'!F9 -> 0 | R8: =IF(B8="",0,((D8/100)*'⚙️ Rate Card'!C7+F8*'⚙️ Rate Card'!C9+G8*'⚙️ Rate Card'!C10+H8*'⚙️ Rate Card'!C11+I8*'⚙️ Rate Card'!C12+J8*'⚙️ Rate Card'!C13+K8*'⚙️ Rate Card'!C14+(D8/100)*'⚙️ Rate Card'!C8+L8*IF(OR(O8="N/A",O8="None",O8=""),0,IF(O8="High",'⚙️ Rate Card'!C20,IF(O8="Medium",'⚙️ Rate Card'!C19,'⚙️ Rate Card'!C18)))+M8*IF(OR(P8="Decommission",P8=""),'⚙️ Rate Card'!C29,IF(P8="EC2 (Lift & Shift)",'⚙️ Rate Card'!C25,IF(P8="AWS QuickSight",'⚙️ Rate Card'!C27,IF(P8="Power BI",'⚙️ Rate Card'!C28,IF(P8="Custom Reporting Solution",'⚙️ Rate Card'!C26,0)))))+IF(B8="",0,'⚙️ Rate Card'!C33+(D8/100)*'⚙️ Rate Card'!C34))*'⚙️ Rate Card'!C37+(D8/100)*'⚙️ Rate Card'!C7+F8*'⚙️ Rate Card'!C9+G8*'⚙️ Rate Card'!C10+H8*'⚙️ Rate Card'!C11+I8*'⚙️ Rate Card'!C12+J8*'⚙️ Rate Card'!C13+K8*'⚙️ Rate Card'!C14+(D8/100)*'⚙️ Rate Card'!C8+(D8/100)*'⚙️ Rate Card'!C8+L8*IF(OR(O8="N/A",O8="None",O8=""),0,IF(O8="High",'⚙️ Rate Card'!C20,IF(O8="Medium",'⚙️ Rate Card'!C19,'⚙️ Rate Card'!C18)))+M8*IF(OR(P8="Decommission",P8=""),'⚙️ Rate Card'!C29,IF(P8="EC2 (Lift & Shift)",'⚙️ Rate Card'!C25,IF(P8="AWS QuickSight",'⚙️ Rate Card'!C27,IF(P8="Power BI",'⚙️ Rate Card'!C28,IF(P8="Custom Reporting Solution",'⚙️ Rate Card'!C26,0)))))+IF(B8="",0,'⚙️ Rate Card'!C33+(D8/100)*'⚙️ Rate Card'!C34)+((D8/100)*'⚙️ Rate Card'!C7+F8*'⚙️ Rate Card'!C9+G8*'⚙️ Rate Card'!C10+H8*'⚙️ Rate Card'!C11+I8*'⚙️ Rate Card'!C12+J8*'⚙️ Rate Card'!C13+K8*'⚙️ Rate Card'!C14+(D8/100)*'⚙️ Rate Card'!C8+L8*IF(OR(O8="N/A",O8="None",O8=""),0,IF(O8="High",'⚙️ Rate Card'!C20,IF(O8="Medium",'⚙️ Rate Card'!C19,'⚙️ Rate Card'!C18)))+M8*IF(OR(P8="Decommission",P8=""),'⚙️ Rate Card'!C29,IF(P8="EC2 (Lift & Shift)",'⚙️ Rate Card'!C25,IF(P8="AWS QuickSight",'⚙️ Rate Card'!C27,IF(P8="Power BI",'⚙️ Rate Card'!C28,IF(P8="Custom Reporting Solution",'⚙️ Rate Card'!C26,0)))))+IF(B8="",0,'⚙️ Rate Card'!C33+(D8/100)*'⚙️ Rate Card'!C34))*'⚙️ Rate Card'!C35+((D8/100)*'⚙️ Rate Card'!C7+F8*'⚙️ Rate Card'!C9+G8*'⚙️ Rate Card'!C10+H8*'⚙️ Rate Card'!C11+I8*'⚙️ Rate Card'!C12+J8*'⚙️ Rate Card'!C13+K8*'⚙️ Rate Card'!C14+(D8/100)*'⚙️ Rate Card'!C8+L8*IF(OR(O8="N/A",O8="None",O8=""),0,IF(O8="High",'⚙️ Rate Card'!C20,IF(O8="Medium",'⚙️ Rate Card'!C19,'⚙️ Rate Card'!C18)))+M8*IF(OR(P8="Decommission",P8=""),'⚙️ Rate Card'!C29,IF(P8="EC2 (Lift & Shift)",'⚙️ Rate Card'!C25,IF(P8="AWS QuickSight",'⚙️ Rate Card'!C27,IF(P8="Power BI",'⚙️ Rate Card'!C28,IF(P8="Custom Reporting Solution",'⚙️ Rate Card'!C26,0)))))+IF(B8="",0,'⚙️ Rate Card'!C33+(D8/100)*'⚙️ Rate Card'!C34))*'⚙️ Rate Card'!C36) -> 0 | S8: =IF(B8="",0,(((D8/100)*'⚙️ Rate Card'!C7+F8*'⚙️ Rate Card'!C9+G8*'⚙️ Rate Card'!C10+H8*'⚙️ Rate Card'!C11+I8*'⚙️ Rate Card'!C12+J8*'⚙️ Rate Card'!C13+K8*'⚙️ Rate Card'!C14+(D8/100)*'⚙️ Rate Card'!C8+L8*IF(OR(O8="N/A",O8="None",O8=""),0,IF(O8="High",'⚙️ Rate Card'!C20,IF(O8="Medium",'⚙️ Rate Card'!C19,'⚙️ Rate Card'!C18)))+M8*IF(OR(P8="Decommission",P8=""),'⚙️ Rate Card'!C29,IF(P8="EC2 (Lift & Shift)",'⚙️ Rate Card'!C25,IF(P8="AWS QuickSight",'⚙️ Rate Card'!C27,IF(P8="Power BI",'⚙️ Rate Card'!C28,IF(P8="Custom Reporting Solution",'⚙️ Rate Card'!C26,0)))))+IF(B8="",0,'⚙️ Rate Card'!C33+(D8/100)*'⚙️ Rate Card'!C34))*'⚙️ Rate Card'!C37)*(1-'📊 Dashboard'!C10/100)+(((D8/100)*'⚙️ Rate Card'!C7+F8*'⚙️ Rate Card'!C9+G8*'⚙️ Rate Card'!C10+H8*'⚙️ Rate Card'!C11+I8*'⚙️ Rate Card'!C12+J8*'⚙️ Rate Card'!C13+K8*'⚙️ Rate Card'!C14+(D8/100)*'⚙️ Rate Card'!C8+(D8/100)*'⚙️ Rate Card'!C8))*(1-'📊 Dashboard'!C10/100)+(L8*IF(OR(O8="N/A",O8="None",O8=""),0,IF(O8="High",'⚙️ Rate Card'!C20,IF(O8="Medium",'⚙️ Rate Card'!C19,'⚙️ Rate Card'!C18))))*(1-'📊 Dashboard'!C11/100)+(M8*IF(OR(P8="Decommission",P8=""),'⚙️ Rate Card'!C29,IF(P8="EC2 (Lift & Shift)",'⚙️ Rate Card'!C25,IF(P8="AWS QuickSight",'⚙️ Rate Card'!C27,IF(P8="Power BI",'⚙️ Rate Card'!C28,IF(P8="Custom Reporting Solution",'⚙️ Rate Card'!C26,0))))))*(1-'📊 Dashboard'!C12/100)+(IF(B8="",0,'⚙️ Rate Card'!C33+(D8/100)*'⚙️ Rate Card'!C34))*(1-'📊 Dashboard'!C10/100)+(((D8/100)*'⚙️ Rate Card'!C7+F8*'⚙️ Rate Card'!C9+G8*'⚙️ Rate Card'!C10+H8*'⚙️ Rate Card'!C11+I8*'⚙️ Rate Card'!C12+J8*'⚙️ Rate Card'!C13+K8*'⚙️ Rate Card'!C14+(D8/100)*'⚙️ Rate Card'!C8+L8*IF(OR(O8="N/A",O8="None",O8=""),0,IF(O8="High",'⚙️ Rate Card'!C20,IF(O8="Medium",'⚙️ Rate Card'!C19,'⚙️ Rate Card'!C18)))+M8*IF(OR(P8="Decommission",P8=""),'⚙️ Rate Card'!C29,IF(P8="EC2 (Lift & Shift)",'⚙️ Rate Card'!C25,IF(P8="AWS QuickSight",'⚙️ Rate Card'!C27,IF(P8="Power BI",'⚙️ Rate Card'!C28,IF(P8="Custom Reporting Solution",'⚙️ Rate Card'!C26,0)))))+IF(B8="",0,'⚙️ Rate Card'!C33+(D8/100)*'⚙️ Rate Card'!C34))*'⚙️ Rate Card'!C35)*(1-'📊 Dashboard'!C13/100)+(((D8/100)*'⚙️ Rate Card'!C7+F8*'⚙️ Rate Card'!C9+G8*'⚙️ Rate Card'!C10+H8*'⚙️ Rate Card'!C11+I8*'⚙️ Rate Card'!C12+J8*'⚙️ Rate Card'!C13+K8*'⚙️ Rate Card'!C14+(D8/100)*'⚙️ Rate Card'!C8+L8*IF(OR(O8="N/A",O8="None",O8=""),0,IF(O8="High",'⚙️ Rate Card'!C20,IF(O8="Medium",'⚙️ Rate Card'!C19,'⚙️ Rate Card'!C18)))+M8*IF(OR(P8="Decommission",P8=""),'⚙️ Rate Card'!C29,IF(P8="EC2 (Lift & Shift)",'⚙️ Rate Card'!C25,IF(P8="AWS QuickSight",'⚙️ Rate Card'!C27,IF(P8="Power BI",'⚙️ Rate Card'!C28,IF(P8="Custom Reporting Solution",'⚙️ Rate Card'!C26,0)))))+IF(B8="",0,'⚙️ Rate Card'!C33+(D8/100)*'⚙️ Rate Card'!C34))*'⚙️ Rate Card'!C36)*(1-'📊 Dashboard'!C10/100)) -> 0 | T8: =IF(B8="",0,S8*(1+'📊 Dashboard'!C14/100)) -> 0 | U8: =IF(B8="",0,((D8/100)*'⚙️ Rate Card'!C7+F8*'⚙️ Rate Card'!C9+G8*'⚙️ Rate Card'!C10+H8*'⚙️ Rate Card'!C11+I8*'⚙️ Rate Card'!C12+J8*'⚙️ Rate Card'!C13+K8*'⚙️ Rate Card'!C14+(D8/100)*'⚙️ Rate Card'!C8+L8*IF(OR(O8="N/A",O8="None",O8=""),0,IF(O8="High",'⚙️ Rate Card'!C20,IF(O8="Medium",'⚙️ Rate Card'!C19,'⚙️ Rate Card'!C18)))+M8*IF(OR(P8="Decommission",P8=""),'⚙️ Rate Card'!C29,IF(P8="EC2 (Lift & Shift)",'⚙️ Rate Card'!C25,IF(P8="AWS QuickSight",'⚙️ Rate Card'!C27,IF(P8="Power BI",'⚙️ Rate Card'!C28,IF(P8="Custom Reporting Solution",'⚙️ Rate Card'!C26,0)))))+IF(B8="",0,'⚙️ Rate Card'!C33+(D8/100)*'⚙️ Rate Card'!C34))*'⚙️ Rate Card'!C37) -> 0 | V8: =IF(B8="",0,(D8/100)*'⚙️ Rate Card'!C7+F8*'⚙️ Rate Card'!C9+G8*'⚙️ Rate Card'!C10+H8*'⚙️ Rate Card'!C11+I8*'⚙️ Rate Card'!C12+J8*'⚙️ Rate Card'!C13+K8*'⚙️ Rate Card'!C14+(D8/100)*'⚙️ Rate Card'!C8+(D8/100)*'⚙️ Rate Card'!C8) -> 0 | W8: =IF(B8="",0,L8*IF(OR(O8="N/A",O8="None",O8=""),0,IF(O8="High",'⚙️ Rate Card'!C20,IF(O8="Medium",'⚙️ Rate Card'!C19,'⚙️ Rate Card'!C18)))) -> 0 | X8: =IF(B8="",0,M8*IF(OR(P8="Decommission",P8=""),'⚙️ Rate Card'!C29,IF(P8="EC2 (Lift & Shift)",'⚙️ Rate Card'!C25,IF(P8="AWS QuickSight",'⚙️ Rate Card'!C27,IF(P8="Power BI",'⚙️ Rate Card'!C28,IF(P8="Custom Reporting Solution",'⚙️ Rate Card'!C26,0)))))) -> 0 | Y8: =IF(B8="",0,IF(B8="",0,'⚙️ Rate Card'!C33+(D8/100)*'⚙️ Rate Card'!C34)) -> 0 | Z8: =IF(B8="",0,((D8/100)*'⚙️ Rate Card'!C7+F8*'⚙️ Rate Card'!C9+G8*'⚙️ Rate Card'!C10+H8*'⚙️ Rate Card'!C11+I8*'⚙️ Rate Card'!C12+J8*'⚙️ Rate Card'!C13+K8*'⚙️ Rate Card'!C14+(D8/100)*'⚙️ Rate Card'!C8+L8*IF(OR(O8="N/A",O8="None",O8=""),0,IF(O8="High",'⚙️ Rate Card'!C20,IF(O8="Medium",'⚙️ Rate Card'!C19,'⚙️ Rate Card'!C18)))+M8*IF(OR(P8="Decommission",P8=""),'⚙️ Rate Card'!C29,IF(P8="EC2 (Lift & Shift)",'⚙️ Rate Card'!C25,IF(P8="AWS QuickSight",'⚙️ Rate Card'!C27,IF(P8="Power BI",'⚙️ Rate Card'!C28,IF(P8="Custom Reporting Solution",'⚙️ Rate Card'!C26,0)))))+IF(B8="",0,'⚙️ Rate Card'!C33+(D8/100)*'⚙️ Rate Card'!C34))*'⚙️ Rate Card'!C35) -> 0 | AA8: =IF(B8="",0,((D8/100)*'⚙️ Rate Card'!C7+F8*'⚙️ Rate Card'!C9+G8*'⚙️ Rate Card'!C10+H8*'⚙️ Rate Card'!C11+I8*'⚙️ Rate Card'!C12+J8*'⚙️ Rate Card'!C13+K8*'⚙️ Rate Card'!C14+(D8/100)*'⚙️ Rate Card'!C8+L8*IF(OR(O8="N/A",O8="None",O8=""),0,IF(O8="High",'⚙️ Rate Card'!C20,IF(O8="Medium",'⚙️ Rate Card'!C19,'⚙️ Rate Card'!C18)))+M8*IF(OR(P8="Decommission",P8=""),'⚙️ Rate Card'!C29,IF(P8="EC2 (Lift & Shift)",'⚙️ Rate Card'!C25,IF(P8="AWS QuickSight",'⚙️ Rate Card'!C27,IF(P8="Power BI",'⚙️ Rate Card'!C28,IF(P8="Custom Reporting Solution",'⚙️ Rate Card'!C26,0)))))+IF(B8="",0,'⚙️ Rate Card'!C33+(D8/100)*'⚙️ Rate Card'!C34))*'⚙️ Rate Card'!C36) -> 0 | AB8: ='✏️ SME Input'!T9 -> 0 | AC8: =IF(B8="",0,AB8*0.75) -> 0 | AD8: =IF(B8="",0,AB8*0.75) -> 0 | AE8: =IF(B8="",0,AB8*0.75) -> 0 | AF8: =IF(B8="",0,AB8*2.25) -> 0 | AG8: =IF(B8="",0,((D8/100)*'⚙️ Rate Card'!C7+F8*'⚙️ Rate Card'!C9+G8*'⚙️ Rate Card'!C10+H8*'⚙️ Rate Card'!C11+I8*'⚙️ Rate Card'!C12+J8*'⚙️ Rate Card'!C13+K8*'⚙️ Rate Card'!C14+(D8/100)*'⚙️ Rate Card'!C8)*0.4) -> 0 | AH8: =IF(B8="",0,((D8/100)*'⚙️ Rate Card'!C7+F8*'⚙️ Rate Card'!C9+G8*'⚙️ Rate Card'!C10+H8*'⚙️ Rate Card'!C11+I8*'⚙️ Rate Card'!C12+J8*'⚙️ Rate Card'!C13+K8*'⚙️ Rate Card'!C14+(D8/100)*'⚙️ Rate Card'!C8)*0.4) -> 0 | AI8: =IF(B8="",0,((D8/100)*'⚙️ Rate Card'!C7+F8*'⚙️ Rate Card'!C9+G8*'⚙️ Rate Card'!C10+H8*'⚙️ Rate Card'!C11+I8*'⚙️ Rate Card'!C12+J8*'⚙️ Rate Card'!C13+K8*'⚙️ Rate Card'!C14+(D8/100)*'⚙️ Rate Card'!C8)*0.2) -> 0 | AJ8: =IF(B8="",0,(L8*IF(OR(O8="N/A",O8="None",O8=""),0,IF(O8="High",'⚙️ Rate Card'!C20,IF(O8="Medium",'⚙️ Rate Card'!C19,'⚙️ Rate Card'!C18))))*0.5) -> 0 | AK8: =IF(B8="",0,(L8*IF(OR(O8="N/A",O8="None",O8=""),0,IF(O8="High",'⚙️ Rate Card'!C20,IF(O8="Medium",'⚙️ Rate Card'!C19,'⚙️ Rate Card'!C18))))*0.35) -> 0 | AL8: =IF(B8="",0,(L8*IF(OR(O8="N/A",O8="None",O8=""),0,IF(O8="High",'⚙️ Rate Card'!C20,IF(O8="Medium",'⚙️ Rate Card'!C19,'⚙️ Rate Card'!C18))))*0.15) -> 0 | AM8: =IF(B8="",0,AG8+AJ8+(M8*IF(OR(P8="Decommission",P8=""),'⚙️ Rate Card'!C29,IF(P8="EC2 (Lift & Shift)",'⚙️ Rate Card'!C25,IF(P8="AWS QuickSight",'⚙️ Rate Card'!C27,IF(P8="Power BI",'⚙️ Rate Card'!C28,IF(P8="Custom Reporting Solution",'⚙️ Rate Card'!C26,0))))))*0.4+(IF(B8="",0,'⚙️ Rate Card'!C33+(D8/100)*'⚙️ Rate Card'!C34))*0.4+AC8+(((D8/100)*'⚙️ Rate Card'!C7+F8*'⚙️ Rate Card'!C9+G8*'⚙️ Rate Card'!C10+H8*'⚙️ Rate Card'!C11+I8*'⚙️ Rate Card'!C12+J8*'⚙️ Rate Card'!C13+K8*'⚙️ Rate Card'!C14+(D8/100)*'⚙️ Rate Card'!C8+L8*IF(OR(O8="N/A",O8="None",O8=""),0,IF(O8="High",'⚙️ Rate Card'!C20,IF(O8="Medium",'⚙️ Rate Card'!C19,'⚙️ Rate Card'!C18)))+M8*IF(OR(P8="Decommission",P8=""),'⚙️ Rate Card'!C29,IF(P8="EC2 (Lift & Shift)",'⚙️ Rate Card'!C25,IF(P8="AWS QuickSight",'⚙️ Rate Card'!C27,IF(P8="Power BI",'⚙️ Rate Card'!C28,IF(P8="Custom Reporting Solution",'⚙️ Rate Card'!C26,0)))))+IF(B8="",0,'⚙️ Rate Card'!C33+(D8/100)*'⚙️ Rate Card'!C34)))*'⚙️ Rate Card'!C35*0.4+(((D8/100)*'⚙️ Rate Card'!C7+F8*'⚙️ Rate Card'!C9+G8*'⚙️ Rate Card'!C10+H8*'⚙️ Rate Card'!C11+I8*'⚙️ Rate Card'!C12+J8*'⚙️ Rate Card'!C13+K8*'⚙️ Rate Card'!C14+(D8/100)*'⚙️ Rate Card'!C8+L8*IF(OR(O8="N/A",O8="None",O8=""),0,IF(O8="High",'⚙️ Rate Card'!C20,IF(O8="Medium",'⚙️ Rate Card'!C19,'⚙️ Rate Card'!C18)))+M8*IF(OR(P8="Decommission",P8=""),'⚙️ Rate Card'!C29,IF(P8="EC2 (Lift & Shift)",'⚙️ Rate Card'!C25,IF(P8="AWS QuickSight",'⚙️ Rate Card'!C27,IF(P8="Power BI",'⚙️ Rate Card'!C28,IF(P8="Custom Reporting Solution",'⚙️ Rate Card'!C26,0)))))+IF(B8="",0,'⚙️ Rate Card'!C33+(D8/100)*'⚙️ Rate Card'!C34)))*'⚙️ Rate Card'!C36*0.4+(((D8/100)*'⚙️ Rate Card'!C7+F8*'⚙️ Rate Card'!C9+G8*'⚙️ Rate Card'!C10+H8*'⚙️ Rate Card'!C11+I8*'⚙️ Rate Card'!C12+J8*'⚙️ Rate Card'!C13+K8*'⚙️ Rate Card'!C14+(D8/100)*'⚙️ Rate Card'!C8+L8*IF(OR(O8="N/A",O8="None",O8=""),0,IF(O8="High",'⚙️ Rate Card'!C20,IF(O8="Medium",'⚙️ Rate Card'!C19,'⚙️ Rate Card'!C18)))+M8*IF(OR(P8="Decommission",P8=""),'⚙️ Rate Card'!C29,IF(P8="EC2 (Lift & Shift)",'⚙️ Rate Card'!C25,IF(P8="AWS QuickSight",'⚙️ Rate Card'!C27,IF(P8="Power BI",'⚙️ Rate Card'!C28,IF(P8="Custom Reporting Solution",'⚙️ Rate Card'!C26,0)))))+IF(B8="",0,'⚙️ Rate Card'!C33+(D8/100)*'⚙️ Rate Card'!C34)))*'⚙️ Rate Card'!C37*0.4) -> 0 | AN8: =IF(B8="",0,AH8+AK8+(M8*IF(OR(P8="Decommission",P8=""),'⚙️ Rate Card'!C29,IF(P8="EC2 (Lift & Shift)",'⚙️ Rate Card'!C25,IF(P8="AWS QuickSight",'⚙️ Rate Card'!C27,IF(P8="Power BI",'⚙️ Rate Card'!C28,IF(P8="Custom Reporting Solution",'⚙️ Rate Card'!C26,0))))))*0.4+(IF(B8="",0,'⚙️ Rate Card'!C33+(D8/100)*'⚙️ Rate Card'!C34))*0.4+AD8+(((D8/100)*'⚙️ Rate Card'!C7+F8*'⚙️ Rate Card'!C9+G8*'⚙️ Rate Card'!C10+H8*'⚙️ Rate Card'!C11+I8*'⚙️ Rate Card'!C12+J8*'⚙️ Rate Card'!C13+K8*'⚙️ Rate Card'!C14+(D8/100)*'⚙️ Rate Card'!C8+L8*IF(OR(O8="N/A",O8="None",O8=""),0,IF(O8="High",'⚙️ Rate Card'!C20,IF(O8="Medium",'⚙️ Rate Card'!C19,'⚙️ Rate Card'!C18)))+M8*IF(OR(P8="Decommission",P8=""),'⚙️ Rate Card'!C29,IF(P8="EC2 (Lift & Shift)",'⚙️ Rate Card'!C25,IF(P8="AWS QuickSight",'⚙️ Rate Card'!C27,IF(P8="Power BI",'⚙️ Rate Card'!C28,IF(P8="Custom Reporting Solution",'⚙️ Rate Card'!C26,0)))))+IF(B8="",0,'⚙️ Rate Card'!C33+(D8/100)*'⚙️ Rate Card'!C34)))*'⚙️ Rate Card'!C35*0.4+(((D8/100)*'⚙️ Rate Card'!C7+F8*'⚙️ Rate Card'!C9+G8*'⚙️ Rate Card'!C10+H8*'⚙️ Rate Card'!C11+I8*'⚙️ Rate Card'!C12+J8*'⚙️ Rate Card'!C13+K8*'⚙️ Rate Card'!C14+(D8/100)*'⚙️ Rate Card'!C8+L8*IF(OR(O8="N/A",O8="None",O8=""),0,IF(O8="High",'⚙️ Rate Card'!C20,IF(O8="Medium",'⚙️ Rate Card'!C19,'⚙️ Rate Card'!C18)))+M8*IF(OR(P8="Decommission",P8=""),'⚙️ Rate Card'!C29,IF(P8="EC2 (Lift & Shift)",'⚙️ Rate Card'!C25,IF(P8="AWS QuickSight",'⚙️ Rate Card'!C27,IF(P8="Power BI",'⚙️ Rate Card'!C28,IF(P8="Custom Reporting Solution",'⚙️ Rate Card'!C26,0)))))+IF(B8="",0,'⚙️ Rate Card'!C33+(D8/100)*'⚙️ Rate Card'!C34)))*'⚙️ Rate Card'!C36*0.4+(((D8/100)*'⚙️ Rate Card'!C7+F8*'⚙️ Rate Card'!C9+G8*'⚙️ Rate Card'!C10+H8*'⚙️ Rate Card'!C11+I8*'⚙️ Rate Card'!C12+J8*'⚙️ Rate Card'!C13+K8*'⚙️ Rate Card'!C14+(D8/100)*'⚙️ Rate Card'!C8+L8*IF(OR(O8="N/A",O8="None",O8=""),0,IF(O8="High",'⚙️ Rate Card'!C20,IF(O8="Medium",'⚙️ Rate Card'!C19,'⚙️ Rate Card'!C18)))+M8*IF(OR(P8="Decommission",P8=""),'⚙️ Rate Card'!C29,IF(P8="EC2 (Lift & Shift)",'⚙️ Rate Card'!C25,IF(P8="AWS QuickSight",'⚙️ Rate Card'!C27,IF(P8="Power BI",'⚙️ Rate Card'!C28,IF(P8="Custom Reporting Solution",'⚙️ Rate Card'!C26,0)))))+IF(B8="",0,'⚙️ Rate Card'!C33+(D8/100)*'⚙️ Rate Card'!C34)))*'⚙️ Rate Card'!C37*0.4) -> 0 | AO8: =IF(B8="",0,AI8+AL8+(M8*IF(OR(P8="Decommission",P8=""),'⚙️ Rate Card'!C29,IF(P8="EC2 (Lift & Shift)",'⚙️ Rate Card'!C25,IF(P8="AWS QuickSight",'⚙️ Rate Card'!C27,IF(P8="Power BI",'⚙️ Rate Card'!C28,IF(P8="Custom Reporting Solution",'⚙️ Rate Card'!C26,0))))))*0.2+(IF(B8="",0,'⚙️ Rate Card'!C33+(D8/100)*'⚙️ Rate Card'!C34))*0.2+AE8+(((D8/100)*'⚙️ Rate Card'!C7+F8*'⚙️ Rate Card'!C9+G8*'⚙️ Rate Card'!C10+H8*'⚙️ Rate Card'!C11+I8*'⚙️ Rate Card'!C12+J8*'⚙️ Rate Card'!C13+K8*'⚙️ Rate Card'!C14+(D8/100)*'⚙️ Rate Card'!C8+L8*IF(OR(O8="N/A",O8="None",O8=""),0,IF(O8="High",'⚙️ Rate Card'!C20,IF(O8="Medium",'⚙️ Rate Card'!C19,'⚙️ Rate Card'!C18)))+M8*IF(OR(P8="Decommission",P8=""),'⚙️ Rate Card'!C29,IF(P8="EC2 (Lift & Shift)",'⚙️ Rate Card'!C25,IF(P8="AWS QuickSight",'⚙️ Rate Card'!C27,IF(P8="Power BI",'⚙️ Rate Card'!C28,IF(P8="Custom Reporting Solution",'⚙️ Rate Card'!C26,0)))))+IF(B8="",0,'⚙️ Rate Card'!C33+(D8/100)*'⚙️ Rate Card'!C34)))*'⚙️ Rate Card'!C35*0.2+(((D8/100)*'⚙️ Rate Card'!C7+F8*'⚙️ Rate Card'!C9+G8*'⚙️ Rate Card'!C10+H8*'⚙️ Rate Card'!C11+I8*'⚙️ Rate Card'!C12+J8*'⚙️ Rate Card'!C13+K8*'⚙️ Rate Card'!C14+(D8/100)*'⚙️ Rate Card'!C8+L8*IF(OR(O8="N/A",O8="None",O8=""),0,IF(O8="High",'⚙️ Rate Card'!C20,IF(O8="Medium",'⚙️ Rate Card'!C19,'⚙️ Rate Card'!C18)))+M8*IF(OR(P8="Decommission",P8=""),'⚙️ Rate Card'!C29,IF(P8="EC2 (Lift & Shift)",'⚙️ Rate Card'!C25,IF(P8="AWS QuickSight",'⚙️ Rate Card'!C27,IF(P8="Power BI",'⚙️ Rate Card'!C28,IF(P8="Custom Reporting Solution",'⚙️ Rate Card'!C26,0)))))+IF(B8="",0,'⚙️ Rate Card'!C33+(D8/100)*'⚙️ Rate Card'!C34)))*'⚙️ Rate Card'!C36*0.2+(((D8/100)*'⚙️ Rate Card'!C7+F8*'⚙️ Rate Card'!C9+G8*'⚙️ Rate Card'!C10+H8*'⚙️ Rate Card'!C11+I8*'⚙️ Rate Card'!C12+J8*'⚙️ Rate Card'!C13+K8*'⚙️ Rate Card'!C14+(D8/100)*'⚙️ Rate Card'!C8+L8*IF(OR(O8="N/A",O8="None",O8=""),0,IF(O8="High",'⚙️ Rate Card'!C20,IF(O8="Medium",'⚙️ Rate Card'!C19,'⚙️ Rate Card'!C18)))+M8*IF(OR(P8="Decommission",P8=""),'⚙️ Rate Card'!C29,IF(P8="EC2 (Lift & Shift)",'⚙️ Rate Card'!C25,IF(P8="AWS QuickSight",'⚙️ Rate Card'!C27,IF(P8="Power BI",'⚙️ Rate Card'!C28,IF(P8="Custom Reporting Solution",'⚙️ Rate Card'!C26,0)))))+IF(B8="",0,'⚙️ Rate Card'!C33+(D8/100)*'⚙️ Rate Card'!C34)))*'⚙️ Rate Card'!C37*0.2) -> 0 | AP8: ='✏️ SME Input'!B9 -> 0 | AQ8: ='✏️ SME Input'!C9 -> 0 | AR8: ='✏️ SME Input'!D9 -> 0
B9: ='✏️ SME Input'!E10 -> 0 | C9: =IF(B9="","",IF(D9>1000,"T3 Complex",IF(D9>500,"T2 Moderate","T1 Simple"))) | D9: ='✏️ SME Input'!G10 -> 0 | E9: ='✏️ SME Input'!H10 -> 0 | F9: ='✏️ SME Input'!I10 -> 0 | G9: ='✏️ SME Input'!J10 -> 0 | H9: ='✏️ SME Input'!K10 -> 0 | I9: ='✏️ SME Input'!L10 -> 0 | J9: ='✏️ SME Input'!M10 -> 0 | K9: ='✏️ SME Input'!N10 -> 0 | ... P9: ='✏️ SME Input'!S10 -> 0 | Q9: ='✏️ SME Input'!F10 -> 0 | R9: =IF(B9="",0,((D9/100)*'⚙️ Rate Card'!C7+F9*'⚙️ Rate Card'!C9+G9*'⚙️ Rate Card'!C10+H9*'⚙️ Rate Card'!C11+I9*'⚙️ Rate Card'!C12+J9*'⚙️ Rate Card'!C13+K9*'⚙️ Rate Card'!C14+(D9/100)*'⚙️ Rate Card'!C8+L9*IF(OR(O9="N/A",O9="None",O9=""),0,IF(O9="High",'⚙️ Rate Card'!C20,IF(O9="Medium",'⚙️ Rate Card'!C19,'⚙️ Rate Card'!C18)))+M9*IF(OR(P9="Decommission",P9=""),'⚙️ Rate Card'!C29,IF(P9="EC2 (Lift & Shift)",'⚙️ Rate Card'!C25,IF(P9="AWS QuickSight",'⚙️ Rate Card'!C27,IF(P9="Power BI",'⚙️ Rate Card'!C28,IF(P9="Custom Reporting Solution",'⚙️ Rate Card'!C26,0)))))+IF(B9="",0,'⚙️ Rate Card'!C33+(D9/100)*'⚙️ Rate Card'!C34))*'⚙️ Rate Card'!C37+(D9/100)*'⚙️ Rate Card'!C7+F9*'⚙️ Rate Card'!C9+G9*'⚙️ Rate Card'!C10+H9*'⚙️ Rate Card'!C11+I9*'⚙️ Rate Card'!C12+J9*'⚙️ Rate Card'!C13+K9*'⚙️ Rate Card'!C14+(D9/100)*'⚙️ Rate Card'!C8+(D9/100)*'⚙️ Rate Card'!C8+L9*IF(OR(O9="N/A",O9="None",O9=""),0,IF(O9="High",'⚙️ Rate Card'!C20,IF(O9="Medium",'⚙️ Rate Card'!C19,'⚙️ Rate Card'!C18)))+M9*IF(OR(P9="Decommission",P9=""),'⚙️ Rate Card'!C29,IF(P9="EC2 (Lift & Shift)",'⚙️ Rate Card'!C25,IF(P9="AWS QuickSight",'⚙️ Rate Card'!C27,IF(P9="Power BI",'⚙️ Rate Card'!C28,IF(P9="Custom Reporting Solution",'⚙️ Rate Card'!C26,0)))))+IF(B9="",0,'⚙️ Rate Card'!C33+(D9/100)*'⚙️ Rate Card'!C34)+((D9/100)*'⚙️ Rate Card'!C7+F9*'⚙️ Rate Card'!C9+G9*'⚙️ Rate Card'!C10+H9*'⚙️ Rate Card'!C11+I9*'⚙️ Rate Card'!C12+J9*'⚙️ Rate Card'!C13+K9*'⚙️ Rate Card'!C14+(D9/100)*'⚙️ Rate Card'!C8+L9*IF(OR(O9="N/A",O9="None",O9=""),0,IF(O9="High",'⚙️ Rate Card'!C20,IF(O9="Medium",'⚙️ Rate Card'!C19,'⚙️ Rate Card'!C18)))+M9*IF(OR(P9="Decommission",P9=""),'⚙️ Rate Card'!C29,IF(P9="EC2 (Lift & Shift)",'⚙️ Rate Card'!C25,IF(P9="AWS QuickSight",'⚙️ Rate Card'!C27,IF(P9="Power BI",'⚙️ Rate Card'!C28,IF(P9="Custom Reporting Solution",'⚙️ Rate Card'!C26,0)))))+IF(B9="",0,'⚙️ Rate Card'!C33+(D9/100)*'⚙️ Rate Card'!C34))*'⚙️ Rate Card'!C35+((D9/100)*'⚙️ Rate Card'!C7+F9*'⚙️ Rate Card'!C9+G9*'⚙️ Rate Card'!C10+H9*'⚙️ Rate Card'!C11+I9*'⚙️ Rate Card'!C12+J9*'⚙️ Rate Card'!C13+K9*'⚙️ Rate Card'!C14+(D9/100)*'⚙️ Rate Card'!C8+L9*IF(OR(O9="N/A",O9="None",O9=""),0,IF(O9="High",'⚙️ Rate Card'!C20,IF(O9="Medium",'⚙️ Rate Card'!C19,'⚙️ Rate Card'!C18)))+M9*IF(OR(P9="Decommission",P9=""),'⚙️ Rate Card'!C29,IF(P9="EC2 (Lift & Shift)",'⚙️ Rate Card'!C25,IF(P9="AWS QuickSight",'⚙️ Rate Card'!C27,IF(P9="Power BI",'⚙️ Rate Card'!C28,IF(P9="Custom Reporting Solution",'⚙️ Rate Card'!C26,0)))))+IF(B9="",0,'⚙️ Rate Card'!C33+(D9/100)*'⚙️ Rate Card'!C34))*'⚙️ Rate Card'!C36) -> 0 | S9: =IF(B9="",0,(((D9/100)*'⚙️ Rate Card'!C7+F9*'⚙️ Rate Card'!C9+G9*'⚙️ Rate Card'!C10+H9*'⚙️ Rate Card'!C11+I9*'⚙️ Rate Card'!C12+J9*'⚙️ Rate Card'!C13+K9*'⚙️ Rate Card'!C14+(D9/100)*'⚙️ Rate Card'!C8+L9*IF(OR(O9="N/A",O9="None",O9=""),0,IF(O9="High",'⚙️ Rate Card'!C20,IF(O9="Medium",'⚙️ Rate Card'!C19,'⚙️ Rate Card'!C18)))+M9*IF(OR(P9="Decommission",P9=""),'⚙️ Rate Card'!C29,IF(P9="EC2 (Lift & Shift)",'⚙️ Rate Card'!C25,IF(P9="AWS QuickSight",'⚙️ Rate Card'!C27,IF(P9="Power BI",'⚙️ Rate Card'!C28,IF(P9="Custom Reporting Solution",'⚙️ Rate Card'!C26,0)))))+IF(B9="",0,'⚙️ Rate Card'!C33+(D9/100)*'⚙️ Rate Card'!C34))*'⚙️ Rate Card'!C37)*(1-'📊 Dashboard'!C10/100)+(((D9/100)*'⚙️ Rate Card'!C7+F9*'⚙️ Rate Card'!C9+G9*'⚙️ Rate Card'!C10+H9*'⚙️ Rate Card'!C11+I9*'⚙️ Rate Card'!C12+J9*'⚙️ Rate Card'!C13+K9*'⚙️ Rate Card'!C14+(D9/100)*'⚙️ Rate Card'!C8+(D9/100)*'⚙️ Rate Card'!C8))*(1-'📊 Dashboard'!C10/100)+(L9*IF(OR(O9="N/A",O9="None",O9=""),0,IF(O9="High",'⚙️ Rate Card'!C20,IF(O9="Medium",'⚙️ Rate Card'!C19,'⚙️ Rate Card'!C18))))*(1-'📊 Dashboard'!C11/100)+(M9*IF(OR(P9="Decommission",P9=""),'⚙️ Rate Card'!C29,IF(P9="EC2 (Lift & Shift)",'⚙️ Rate Card'!C25,IF(P9="AWS QuickSight",'⚙️ Rate Card'!C27,IF(P9="Power BI",'⚙️ Rate Card'!C28,IF(P9="Custom Reporting Solution",'⚙️ Rate Card'!C26,0))))))*(1-'📊 Dashboard'!C12/100)+(IF(B9="",0,'⚙️ Rate Card'!C33+(D9/100)*'⚙️ Rate Card'!C34))*(1-'📊 Dashboard'!C10/100)+(((D9/100)*'⚙️ Rate Card'!C7+F9*'⚙️ Rate Card'!C9+G9*'⚙️ Rate Card'!C10+H9*'⚙️ Rate Card'!C11+I9*'⚙️ Rate Card'!C12+J9*'⚙️ Rate Card'!C13+K9*'⚙️ Rate Card'!C14+(D9/100)*'⚙️ Rate Card'!C8+L9*IF(OR(O9="N/A",O9="None",O9=""),0,IF(O9="High",'⚙️ Rate Card'!C20,IF(O9="Medium",'⚙️ Rate Card'!C19,'⚙️ Rate Card'!C18)))+M9*IF(OR(P9="Decommission",P9=""),'⚙️ Rate Card'!C29,IF(P9="EC2 (Lift & Shift)",'⚙️ Rate Card'!C25,IF(P9="AWS QuickSight",'⚙️ Rate Card'!C27,IF(P9="Power BI",'⚙️ Rate Card'!C28,IF(P9="Custom Reporting Solution",'⚙️ Rate Card'!C26,0)))))+IF(B9="",0,'⚙️ Rate Card'!C33+(D9/100)*'⚙️ Rate Card'!C34))*'⚙️ Rate Card'!C35)*(1-'📊 Dashboard'!C13/100)+(((D9/100)*'⚙️ Rate Card'!C7+F9*'⚙️ Rate Card'!C9+G9*'⚙️ Rate Card'!C10+H9*'⚙️ Rate Card'!C11+I9*'⚙️ Rate Card'!C12+J9*'⚙️ Rate Card'!C13+K9*'⚙️ Rate Card'!C14+(D9/100)*'⚙️ Rate Card'!C8+L9*IF(OR(O9="N/A",O9="None",O9=""),0,IF(O9="High",'⚙️ Rate Card'!C20,IF(O9="Medium",'⚙️ Rate Card'!C19,'⚙️ Rate Card'!C18)))+M9*IF(OR(P9="Decommission",P9=""),'⚙️ Rate Card'!C29,IF(P9="EC2 (Lift & Shift)",'⚙️ Rate Card'!C25,IF(P9="AWS QuickSight",'⚙️ Rate Card'!C27,IF(P9="Power BI",'⚙️ Rate Card'!C28,IF(P9="Custom Reporting Solution",'⚙️ Rate Card'!C26,0)))))+IF(B9="",0,'⚙️ Rate Card'!C33+(D9/100)*'⚙️ Rate Card'!C34))*'⚙️ Rate Card'!C36)*(1-'📊 Dashboard'!C10/100)) -> 0 | T9: =IF(B9="",0,S9*(1+'📊 Dashboard'!C14/100)) -> 0 | U9: =IF(B9="",0,((D9/100)*'⚙️ Rate Card'!C7+F9*'⚙️ Rate Card'!C9+G9*'⚙️ Rate Card'!C10+H9*'⚙️ Rate Card'!C11+I9*'⚙️ Rate Card'!C12+J9*'⚙️ Rate Card'!C13+K9*'⚙️ Rate Card'!C14+(D9/100)*'⚙️ Rate Card'!C8+L9*IF(OR(O9="N/A",O9="None",O9=""),0,IF(O9="High",'⚙️ Rate Card'!C20,IF(O9="Medium",'⚙️ Rate Card'!C19,'⚙️ Rate Card'!C18)))+M9*IF(OR(P9="Decommission",P9=""),'⚙️ Rate Card'!C29,IF(P9="EC2 (Lift & Shift)",'⚙️ Rate Card'!C25,IF(P9="AWS QuickSight",'⚙️ Rate Card'!C27,IF(P9="Power BI",'⚙️ Rate Card'!C28,IF(P9="Custom Reporting Solution",'⚙️ Rate Card'!C26,0)))))+IF(B9="",0,'⚙️ Rate Card'!C33+(D9/100)*'⚙️ Rate Card'!C34))*'⚙️ Rate Card'!C37) -> 0 | V9: =IF(B9="",0,(D9/100)*'⚙️ Rate Card'!C7+F9*'⚙️ Rate Card'!C9+G9*'⚙️ Rate Card'!C10+H9*'⚙️ Rate Card'!C11+I9*'⚙️ Rate Card'!C12+J9*'⚙️ Rate Card'!C13+K9*'⚙️ Rate Card'!C14+(D9/100)*'⚙️ Rate Card'!C8+(D9/100)*'⚙️ Rate Card'!C8) -> 0 | W9: =IF(B9="",0,L9*IF(OR(O9="N/A",O9="None",O9=""),0,IF(O9="High",'⚙️ Rate Card'!C20,IF(O9="Medium",'⚙️ Rate Card'!C19,'⚙️ Rate Card'!C18)))) -> 0 | X9: =IF(B9="",0,M9*IF(OR(P9="Decommission",P9=""),'⚙️ Rate Card'!C29,IF(P9="EC2 (Lift & Shift)",'⚙️ Rate Card'!C25,IF(P9="AWS QuickSight",'⚙️ Rate Card'!C27,IF(P9="Power BI",'⚙️ Rate Card'!C28,IF(P9="Custom Reporting Solution",'⚙️ Rate Card'!C26,0)))))) -> 0 | Y9: =IF(B9="",0,IF(B9="",0,'⚙️ Rate Card'!C33+(D9/100)*'⚙️ Rate Card'!C34)) -> 0 | Z9: =IF(B9="",0,((D9/100)*'⚙️ Rate Card'!C7+F9*'⚙️ Rate Card'!C9+G9*'⚙️ Rate Card'!C10+H9*'⚙️ Rate Card'!C11+I9*'⚙️ Rate Card'!C12+J9*'⚙️ Rate Card'!C13+K9*'⚙️ Rate Card'!C14+(D9/100)*'⚙️ Rate Card'!C8+L9*IF(OR(O9="N/A",O9="None",O9=""),0,IF(O9="High",'⚙️ Rate Card'!C20,IF(O9="Medium",'⚙️ Rate Card'!C19,'⚙️ Rate Card'!C18)))+M9*IF(OR(P9="Decommission",P9=""),'⚙️ Rate Card'!C29,IF(P9="EC2 (Lift & Shift)",'⚙️ Rate Card'!C25,IF(P9="AWS QuickSight",'⚙️ Rate Card'!C27,IF(P9="Power BI",'⚙️ Rate Card'!C28,IF(P9="Custom Reporting Solution",'⚙️ Rate Card'!C26,0)))))+IF(B9="",0,'⚙️ Rate Card'!C33+(D9/100)*'⚙️ Rate Card'!C34))*'⚙️ Rate Card'!C35) -> 0 | AA9: =IF(B9="",0,((D9/100)*'⚙️ Rate Card'!C7+F9*'⚙️ Rate Card'!C9+G9*'⚙️ Rate Card'!C10+H9*'⚙️ Rate Card'!C11+I9*'⚙️ Rate Card'!C12+J9*'⚙️ Rate Card'!C13+K9*'⚙️ Rate Card'!C14+(D9/100)*'⚙️ Rate Card'!C8+L9*IF(OR(O9="N/A",O9="None",O9=""),0,IF(O9="High",'⚙️ Rate Card'!C20,IF(O9="Medium",'⚙️ Rate Card'!C19,'⚙️ Rate Card'!C18)))+M9*IF(OR(P9="Decommission",P9=""),'⚙️ Rate Card'!C29,IF(P9="EC2 (Lift & Shift)",'⚙️ Rate Card'!C25,IF(P9="AWS QuickSight",'⚙️ Rate Card'!C27,IF(P9="Power BI",'⚙️ Rate Card'!C28,IF(P9="Custom Reporting Solution",'⚙️ Rate Card'!C26,0)))))+IF(B9="",0,'⚙️ Rate Card'!C33+(D9/100)*'⚙️ Rate Card'!C34))*'⚙️ Rate Card'!C36) -> 0 | AB9: ='✏️ SME Input'!T10 -> 0 | AC9: =IF(B9="",0,AB9*0.75) -> 0 | AD9: =IF(B9="",0,AB9*0.75) -> 0 | AE9: =IF(B9="",0,AB9*0.75) -> 0 | AF9: =IF(B9="",0,AB9*2.25) -> 0 | AG9: =IF(B9="",0,((D9/100)*'⚙️ Rate Card'!C7+F9*'⚙️ Rate Card'!C9+G9*'⚙️ Rate Card'!C10+H9*'⚙️ Rate Card'!C11+I9*'⚙️ Rate Card'!C12+J9*'⚙️ Rate Card'!C13+K9*'⚙️ Rate Card'!C14+(D9/100)*'⚙️ Rate Card'!C8)*0.4) -> 0 | AH9: =IF(B9="",0,((D9/100)*'⚙️ Rate Card'!C7+F9*'⚙️ Rate Card'!C9+G9*'⚙️ Rate Card'!C10+H9*'⚙️ Rate Card'!C11+I9*'⚙️ Rate Card'!C12+J9*'⚙️ Rate Card'!C13+K9*'⚙️ Rate Card'!C14+(D9/100)*'⚙️ Rate Card'!C8)*0.4) -> 0 | AI9: =IF(B9="",0,((D9/100)*'⚙️ Rate Card'!C7+F9*'⚙️ Rate Card'!C9+G9*'⚙️ Rate Card'!C10+H9*'⚙️ Rate Card'!C11+I9*'⚙️ Rate Card'!C12+J9*'⚙️ Rate Card'!C13+K9*'⚙️ Rate Card'!C14+(D9/100)*'⚙️ Rate Card'!C8)*0.2) -> 0 | AJ9: =IF(B9="",0,(L9*IF(OR(O9="N/A",O9="None",O9=""),0,IF(O9="High",'⚙️ Rate Card'!C20,IF(O9="Medium",'⚙️ Rate Card'!C19,'⚙️ Rate Card'!C18))))*0.5) -> 0 | AK9: =IF(B9="",0,(L9*IF(OR(O9="N/A",O9="None",O9=""),0,IF(O9="High",'⚙️ Rate Card'!C20,IF(O9="Medium",'⚙️ Rate Card'!C19,'⚙️ Rate Card'!C18))))*0.35) -> 0 | AL9: =IF(B9="",0,(L9*IF(OR(O9="N/A",O9="None",O9=""),0,IF(O9="High",'⚙️ Rate Card'!C20,IF(O9="Medium",'⚙️ Rate Card'!C19,'⚙️ Rate Card'!C18))))*0.15) -> 0 | AM9: =IF(B9="",0,AG9+AJ9+(M9*IF(OR(P9="Decommission",P9=""),'⚙️ Rate Card'!C29,IF(P9="EC2 (Lift & Shift)",'⚙️ Rate Card'!C25,IF(P9="AWS QuickSight",'⚙️ Rate Card'!C27,IF(P9="Power BI",'⚙️ Rate Card'!C28,IF(P9="Custom Reporting Solution",'⚙️ Rate Card'!C26,0))))))*0.4+(IF(B9="",0,'⚙️ Rate Card'!C33+(D9/100)*'⚙️ Rate Card'!C34))*0.4+AC9+(((D9/100)*'⚙️ Rate Card'!C7+F9*'⚙️ Rate Card'!C9+G9*'⚙️ Rate Card'!C10+H9*'⚙️ Rate Card'!C11+I9*'⚙️ Rate Card'!C12+J9*'⚙️ Rate Card'!C13+K9*'⚙️ Rate Card'!C14+(D9/100)*'⚙️ Rate Card'!C8+L9*IF(OR(O9="N/A",O9="None",O9=""),0,IF(O9="High",'⚙️ Rate Card'!C20,IF(O9="Medium",'⚙️ Rate Card'!C19,'⚙️ Rate Card'!C18)))+M9*IF(OR(P9="Decommission",P9=""),'⚙️ Rate Card'!C29,IF(P9="EC2 (Lift & Shift)",'⚙️ Rate Card'!C25,IF(P9="AWS QuickSight",'⚙️ Rate Card'!C27,IF(P9="Power BI",'⚙️ Rate Card'!C28,IF(P9="Custom Reporting Solution",'⚙️ Rate Card'!C26,0)))))+IF(B9="",0,'⚙️ Rate Card'!C33+(D9/100)*'⚙️ Rate Card'!C34)))*'⚙️ Rate Card'!C35*0.4+(((D9/100)*'⚙️ Rate Card'!C7+F9*'⚙️ Rate Card'!C9+G9*'⚙️ Rate Card'!C10+H9*'⚙️ Rate Card'!C11+I9*'⚙️ Rate Card'!C12+J9*'⚙️ Rate Card'!C13+K9*'⚙️ Rate Card'!C14+(D9/100)*'⚙️ Rate Card'!C8+L9*IF(OR(O9="N/A",O9="None",O9=""),0,IF(O9="High",'⚙️ Rate Card'!C20,IF(O9="Medium",'⚙️ Rate Card'!C19,'⚙️ Rate Card'!C18)))+M9*IF(OR(P9="Decommission",P9=""),'⚙️ Rate Card'!C29,IF(P9="EC2 (Lift & Shift)",'⚙️ Rate Card'!C25,IF(P9="AWS QuickSight",'⚙️ Rate Card'!C27,IF(P9="Power BI",'⚙️ Rate Card'!C28,IF(P9="Custom Reporting Solution",'⚙️ Rate Card'!C26,0)))))+IF(B9="",0,'⚙️ Rate Card'!C33+(D9/100)*'⚙️ Rate Card'!C34)))*'⚙️ Rate Card'!C36*0.4+(((D9/100)*'⚙️ Rate Card'!C7+F9*'⚙️ Rate Card'!C9+G9*'⚙️ Rate Card'!C10+H9*'⚙️ Rate Card'!C11+I9*'⚙️ Rate Card'!C12+J9*'⚙️ Rate Card'!C13+K9*'⚙️ Rate Card'!C14+(D9/100)*'⚙️ Rate Card'!C8+L9*IF(OR(O9="N/A",O9="None",O9=""),0,IF(O9="High",'⚙️ Rate Card'!C20,IF(O9="Medium",'⚙️ Rate Card'!C19,'⚙️ Rate Card'!C18)))+M9*IF(OR(P9="Decommission",P9=""),'⚙️ Rate Card'!C29,IF(P9="EC2 (Lift & Shift)",'⚙️ Rate Card'!C25,IF(P9="AWS QuickSight",'⚙️ Rate Card'!C27,IF(P9="Power BI",'⚙️ Rate Card'!C28,IF(P9="Custom Reporting Solution",'⚙️ Rate Card'!C26,0)))))+IF(B9="",0,'⚙️ Rate Card'!C33+(D9/100)*'⚙️ Rate Card'!C34)))*'⚙️ Rate Card'!C37*0.4) -> 0 | AN9: =IF(B9="",0,AH9+AK9+(M9*IF(OR(P9="Decommission",P9=""),'⚙️ Rate Card'!C29,IF(P9="EC2 (Lift & Shift)",'⚙️ Rate Card'!C25,IF(P9="AWS QuickSight",'⚙️ Rate Card'!C27,IF(P9="Power BI",'⚙️ Rate Card'!C28,IF(P9="Custom Reporting Solution",'⚙️ Rate Card'!C26,0))))))*0.4+(IF(B9="",0,'⚙️ Rate Card'!C33+(D9/100)*'⚙️ Rate Card'!C34))*0.4+AD9+(((D9/100)*'⚙️ Rate Card'!C7+F9*'⚙️ Rate Card'!C9+G9*'⚙️ Rate Card'!C10+H9*'⚙️ Rate Card'!C11+I9*'⚙️ Rate Card'!C12+J9*'⚙️ Rate Card'!C13+K9*'⚙️ Rate Card'!C14+(D9/100)*'⚙️ Rate Card'!C8+L9*IF(OR(O9="N/A",O9="None",O9=""),0,IF(O9="High",'⚙️ Rate Card'!C20,IF(O9="Medium",'⚙️ Rate Card'!C19,'⚙️ Rate Card'!C18)))+M9*IF(OR(P9="Decommission",P9=""),'⚙️ Rate Card'!C29,IF(P9="EC2 (Lift & Shift)",'⚙️ Rate Card'!C25,IF(P9="AWS QuickSight",'⚙️ Rate Card'!C27,IF(P9="Power BI",'⚙️ Rate Card'!C28,IF(P9="Custom Reporting Solution",'⚙️ Rate Card'!C26,0)))))+IF(B9="",0,'⚙️ Rate Card'!C33+(D9/100)*'⚙️ Rate Card'!C34)))*'⚙️ Rate Card'!C35*0.4+(((D9/100)*'⚙️ Rate Card'!C7+F9*'⚙️ Rate Card'!C9+G9*'⚙️ Rate Card'!C10+H9*'⚙️ Rate Card'!C11+I9*'⚙️ Rate Card'!C12+J9*'⚙️ Rate Card'!C13+K9*'⚙️ Rate Card'!C14+(D9/100)*'⚙️ Rate Card'!C8+L9*IF(OR(O9="N/A",O9="None",O9=""),0,IF(O9="High",'⚙️ Rate Card'!C20,IF(O9="Medium",'⚙️ Rate Card'!C19,'⚙️ Rate Card'!C18)))+M9*IF(OR(P9="Decommission",P9=""),'⚙️ Rate Card'!C29,IF(P9="EC2 (Lift & Shift)",'⚙️ Rate Card'!C25,IF(P9="AWS QuickSight",'⚙️ Rate Card'!C27,IF(P9="Power BI",'⚙️ Rate Card'!C28,IF(P9="Custom Reporting Solution",'⚙️ Rate Card'!C26,0)))))+IF(B9="",0,'⚙️ Rate Card'!C33+(D9/100)*'⚙️ Rate Card'!C34)))*'⚙️ Rate Card'!C36*0.4+(((D9/100)*'⚙️ Rate Card'!C7+F9*'⚙️ Rate Card'!C9+G9*'⚙️ Rate Card'!C10+H9*'⚙️ Rate Card'!C11+I9*'⚙️ Rate Card'!C12+J9*'⚙️ Rate Card'!C13+K9*'⚙️ Rate Card'!C14+(D9/100)*'⚙️ Rate Card'!C8+L9*IF(OR(O9="N/A",O9="None",O9=""),0,IF(O9="High",'⚙️ Rate Card'!C20,IF(O9="Medium",'⚙️ Rate Card'!C19,'⚙️ Rate Card'!C18)))+M9*IF(OR(P9="Decommission",P9=""),'⚙️ Rate Card'!C29,IF(P9="EC2 (Lift & Shift)",'⚙️ Rate Card'!C25,IF(P9="AWS QuickSight",'⚙️ Rate Card'!C27,IF(P9="Power BI",'⚙️ Rate Card'!C28,IF(P9="Custom Reporting Solution",'⚙️ Rate Card'!C26,0)))))+IF(B9="",0,'⚙️ Rate Card'!C33+(D9/100)*'⚙️ Rate Card'!C34)))*'⚙️ Rate Card'!C37*0.4) -> 0 | AO9: =IF(B9="",0,AI9+AL9+(M9*IF(OR(P9="Decommission",P9=""),'⚙️ Rate Card'!C29,IF(P9="EC2 (Lift & Shift)",'⚙️ Rate Card'!C25,IF(P9="AWS QuickSight",'⚙️ Rate Card'!C27,IF(P9="Power BI",'⚙️ Rate Card'!C28,IF(P9="Custom Reporting Solution",'⚙️ Rate Card'!C26,0))))))*0.2+(IF(B9="",0,'⚙️ Rate Card'!C33+(D9/100)*'⚙️ Rate Card'!C34))*0.2+AE9+(((D9/100)*'⚙️ Rate Card'!C7+F9*'⚙️ Rate Card'!C9+G9*'⚙️ Rate Card'!C10+H9*'⚙️ Rate Card'!C11+I9*'⚙️ Rate Card'!C12+J9*'⚙️ Rate Card'!C13+K9*'⚙️ Rate Card'!C14+(D9/100)*'⚙️ Rate Card'!C8+L9*IF(OR(O9="N/A",O9="None",O9=""),0,IF(O9="High",'⚙️ Rate Card'!C20,IF(O9="Medium",'⚙️ Rate Card'!C19,'⚙️ Rate Card'!C18)))+M9*IF(OR(P9="Decommission",P9=""),'⚙️ Rate Card'!C29,IF(P9="EC2 (Lift & Shift)",'⚙️ Rate Card'!C25,IF(P9="AWS QuickSight",'⚙️ Rate Card'!C27,IF(P9="Power BI",'⚙️ Rate Card'!C28,IF(P9="Custom Reporting Solution",'⚙️ Rate Card'!C26,0)))))+IF(B9="",0,'⚙️ Rate Card'!C33+(D9/100)*'⚙️ Rate Card'!C34)))*'⚙️ Rate Card'!C35*0.2+(((D9/100)*'⚙️ Rate Card'!C7+F9*'⚙️ Rate Card'!C9+G9*'⚙️ Rate Card'!C10+H9*'⚙️ Rate Card'!C11+I9*'⚙️ Rate Card'!C12+J9*'⚙️ Rate Card'!C13+K9*'⚙️ Rate Card'!C14+(D9/100)*'⚙️ Rate Card'!C8+L9*IF(OR(O9="N/A",O9="None",O9=""),0,IF(O9="High",'⚙️ Rate Card'!C20,IF(O9="Medium",'⚙️ Rate Card'!C19,'⚙️ Rate Card'!C18)))+M9*IF(OR(P9="Decommission",P9=""),'⚙️ Rate Card'!C29,IF(P9="EC2 (Lift & Shift)",'⚙️ Rate Card'!C25,IF(P9="AWS QuickSight",'⚙️ Rate Card'!C27,IF(P9="Power BI",'⚙️ Rate Card'!C28,IF(P9="Custom Reporting Solution",'⚙️ Rate Card'!C26,0)))))+IF(B9="",0,'⚙️ Rate Card'!C33+(D9/100)*'⚙️ Rate Card'!C34)))*'⚙️ Rate Card'!C36*0.2+(((D9/100)*'⚙️ Rate Card'!C7+F9*'⚙️ Rate Card'!C9+G9*'⚙️ Rate Card'!C10+H9*'⚙️ Rate Card'!C11+I9*'⚙️ Rate Card'!C12+J9*'⚙️ Rate Card'!C13+K9*'⚙️ Rate Card'!C14+(D9/100)*'⚙️ Rate Card'!C8+L9*IF(OR(O9="N/A",O9="None",O9=""),0,IF(O9="High",'⚙️ Rate Card'!C20,IF(O9="Medium",'⚙️ Rate Card'!C19,'⚙️ Rate Card'!C18)))+M9*IF(OR(P9="Decommission",P9=""),'⚙️ Rate Card'!C29,IF(P9="EC2 (Lift & Shift)",'⚙️ Rate Card'!C25,IF(P9="AWS QuickSight",'⚙️ Rate Card'!C27,IF(P9="Power BI",'⚙️ Rate Card'!C28,IF(P9="Custom Reporting Solution",'⚙️ Rate Card'!C26,0)))))+IF(B9="",0,'⚙️ Rate Card'!C33+(D9/100)*'⚙️ Rate Card'!C34)))*'⚙️ Rate Card'!C37*0.2) -> 0 | AP9: ='✏️ SME Input'!B10 -> 0 | AQ9: ='✏️ SME Input'!C10 -> 0 | AR9: ='✏️ SME Input'!D10 -> 0
B10: ='✏️ SME Input'!E11 -> 0 | C10: =IF(B10="","",IF(D10>1000,"T3 Complex",IF(D10>500,"T2 Moderate","T1 Simple"))) | D10: ='✏️ SME Input'!G11 -> 0 | E10: ='✏️ SME Input'!H11 -> 0 | F10: ='✏️ SME Input'!I11 -> 0 | G10: ='✏️ SME Input'!J11 -> 0 | H10: ='✏️ SME Input'!K11 -> 0 | I10: ='✏️ SME Input'!L11 -> 0 | J10: ='✏️ SME Input'!M11 -> 0 | K10: ='✏️ SME Input'!N11 -> 0 | ... P10: ='✏️ SME Input'!S11 -> 0 | Q10: ='✏️ SME Input'!F11 -> 0 | R10: =IF(B10="",0,((D10/100)*'⚙️ Rate Card'!C7+F10*'⚙️ Rate Card'!C9+G10*'⚙️ Rate Card'!C10+H10*'⚙️ Rate Card'!C11+I10*'⚙️ Rate Card'!C12+J10*'⚙️ Rate Card'!C13+K10*'⚙️ Rate Card'!C14+(D10/100)*'⚙️ Rate Card'!C8+L10*IF(OR(O10="N/A",O10="None",O10=""),0,IF(O10="High",'⚙️ Rate Card'!C20,IF(O10="Medium",'⚙️ Rate Card'!C19,'⚙️ Rate Card'!C18)))+M10*IF(OR(P10="Decommission",P10=""),'⚙️ Rate Card'!C29,IF(P10="EC2 (Lift & Shift)",'⚙️ Rate Card'!C25,IF(P10="AWS QuickSight",'⚙️ Rate Card'!C27,IF(P10="Power BI",'⚙️ Rate Card'!C28,IF(P10="Custom Reporting Solution",'⚙️ Rate Card'!C26,0)))))+IF(B10="",0,'⚙️ Rate Card'!C33+(D10/100)*'⚙️ Rate Card'!C34))*'⚙️ Rate Card'!C37+(D10/100)*'⚙️ Rate Card'!C7+F10*'⚙️ Rate Card'!C9+G10*'⚙️ Rate Card'!C10+H10*'⚙️ Rate Card'!C11+I10*'⚙️ Rate Card'!C12+J10*'⚙️ Rate Card'!C13+K10*'⚙️ Rate Card'!C14+(D10/100)*'⚙️ Rate Card'!C8+(D10/100)*'⚙️ Rate Card'!C8+L10*IF(OR(O10="N/A",O10="None",O10=""),0,IF(O10="High",'⚙️ Rate Card'!C20,IF(O10="Medium",'⚙️ Rate Card'!C19,'⚙️ Rate Card'!C18)))+M10*IF(OR(P10="Decommission",P10=""),'⚙️ Rate Card'!C29,IF(P10="EC2 (Lift & Shift)",'⚙️ Rate Card'!C25,IF(P10="AWS QuickSight",'⚙️ Rate Card'!C27,IF(P10="Power BI",'⚙️ Rate Card'!C28,IF(P10="Custom Reporting Solution",'⚙️ Rate Card'!C26,0)))))+IF(B10="",0,'⚙️ Rate Card'!C33+(D10/100)*'⚙️ Rate Card'!C34)+((D10/100)*'⚙️ Rate Card'!C7+F10*'⚙️ Rate Card'!C9+G10*'⚙️ Rate Card'!C10+H10*'⚙️ Rate Card'!C11+I10*'⚙️ Rate Card'!C12+J10*'⚙️ Rate Card'!C13+K10*'⚙️ Rate Card'!C14+(D10/100)*'⚙️ Rate Card'!C8+L10*IF(OR(O10="N/A",O10="None",O10=""),0,IF(O10="High",'⚙️ Rate Card'!C20,IF(O10="Medium",'⚙️ Rate Card'!C19,'⚙️ Rate Card'!C18)))+M10*IF(OR(P10="Decommission",P10=""),'⚙️ Rate Card'!C29,IF(P10="EC2 (Lift & Shift)",'⚙️ Rate Card'!C25,IF(P10="AWS QuickSight",'⚙️ Rate Card'!C27,IF(P10="Power BI",'⚙️ Rate Card'!C28,IF(P10="Custom Reporting Solution",'⚙️ Rate Card'!C26,0)))))+IF(B10="",0,'⚙️ Rate Card'!C33+(D10/100)*'⚙️ Rate Card'!C34))*'⚙️ Rate Card'!C35+((D10/100)*'⚙️ Rate Card'!C7+F10*'⚙️ Rate Card'!C9+G10*'⚙️ Rate Card'!C10+H10*'⚙️ Rate Card'!C11+I10*'⚙️ Rate Card'!C12+J10*'⚙️ Rate Card'!C13+K10*'⚙️ Rate Card'!C14+(D10/100)*'⚙️ Rate Card'!C8+L10*IF(OR(O10="N/A",O10="None",O10=""),0,IF(O10="High",'⚙️ Rate Card'!C20,IF(O10="Medium",'⚙️ Rate Card'!C19,'⚙️ Rate Card'!C18)))+M10*IF(OR(P10="Decommission",P10=""),'⚙️ Rate Card'!C29,IF(P10="EC2 (Lift & Shift)",'⚙️ Rate Card'!C25,IF(P10="AWS QuickSight",'⚙️ Rate Card'!C27,IF(P10="Power BI",'⚙️ Rate Card'!C28,IF(P10="Custom Reporting Solution",'⚙️ Rate Card'!C26,0)))))+IF(B10="",0,'⚙️ Rate Card'!C33+(D10/100)*'⚙️ Rate Card'!C34))*'⚙️ Rate Card'!C36) -> 0 | S10: =IF(B10="",0,(((D10/100)*'⚙️ Rate Card'!C7+F10*'⚙️ Rate Card'!C9+G10*'⚙️ Rate Card'!C10+H10*'⚙️ Rate Card'!C11+I10*'⚙️ Rate Card'!C12+J10*'⚙️ Rate Card'!C13+K10*'⚙️ Rate Card'!C14+(D10/100)*'⚙️ Rate Card'!C8+L10*IF(OR(O10="N/A",O10="None",O10=""),0,IF(O10="High",'⚙️ Rate Card'!C20,IF(O10="Medium",'⚙️ Rate Card'!C19,'⚙️ Rate Card'!C18)))+M10*IF(OR(P10="Decommission",P10=""),'⚙️ Rate Card'!C29,IF(P10="EC2 (Lift & Shift)",'⚙️ Rate Card'!C25,IF(P10="AWS QuickSight",'⚙️ Rate Card'!C27,IF(P10="Power BI",'⚙️ Rate Card'!C28,IF(P10="Custom Reporting Solution",'⚙️ Rate Card'!C26,0)))))+IF(B10="",0,'⚙️ Rate Card'!C33+(D10/100)*'⚙️ Rate Card'!C34))*'⚙️ Rate Card'!C37)*(1-'📊 Dashboard'!C10/100)+(((D10/100)*'⚙️ Rate Card'!C7+F10*'⚙️ Rate Card'!C9+G10*'⚙️ Rate Card'!C10+H10*'⚙️ Rate Card'!C11+I10*'⚙️ Rate Card'!C12+J10*'⚙️ Rate Card'!C13+K10*'⚙️ Rate Card'!C14+(D10/100)*'⚙️ Rate Card'!C8+(D10/100)*'⚙️ Rate Card'!C8))*(1-'📊 Dashboard'!C10/100)+(L10*IF(OR(O10="N/A",O10="None",O10=""),0,IF(O10="High",'⚙️ Rate Card'!C20,IF(O10="Medium",'⚙️ Rate Card'!C19,'⚙️ Rate Card'!C18))))*(1-'📊 Dashboard'!C11/100)+(M10*IF(OR(P10="Decommission",P10=""),'⚙️ Rate Card'!C29,IF(P10="EC2 (Lift & Shift)",'⚙️ Rate Card'!C25,IF(P10="AWS QuickSight",'⚙️ Rate Card'!C27,IF(P10="Power BI",'⚙️ Rate Card'!C28,IF(P10="Custom Reporting Solution",'⚙️ Rate Card'!C26,0))))))*(1-'📊 Dashboard'!C12/100)+(IF(B10="",0,'⚙️ Rate Card'!C33+(D10/100)*'⚙️ Rate Card'!C34))*(1-'📊 Dashboard'!C10/100)+(((D10/100)*'⚙️ Rate Card'!C7+F10*'⚙️ Rate Card'!C9+G10*'⚙️ Rate Card'!C10+H10*'⚙️ Rate Card'!C11+I10*'⚙️ Rate Card'!C12+J10*'⚙️ Rate Card'!C13+K10*'⚙️ Rate Card'!C14+(D10/100)*'⚙️ Rate Card'!C8+L10*IF(OR(O10="N/A",O10="None",O10=""),0,IF(O10="High",'⚙️ Rate Card'!C20,IF(O10="Medium",'⚙️ Rate Card'!C19,'⚙️ Rate Card'!C18)))+M10*IF(OR(P10="Decommission",P10=""),'⚙️ Rate Card'!C29,IF(P10="EC2 (Lift & Shift)",'⚙️ Rate Card'!C25,IF(P10="AWS QuickSight",'⚙️ Rate Card'!C27,IF(P10="Power BI",'⚙️ Rate Card'!C28,IF(P10="Custom Reporting Solution",'⚙️ Rate Card'!C26,0)))))+IF(B10="",0,'⚙️ Rate Card'!C33+(D10/100)*'⚙️ Rate Card'!C34))*'⚙️ Rate Card'!C35)*(1-'📊 Dashboard'!C13/100)+(((D10/100)*'⚙️ Rate Card'!C7+F10*'⚙️ Rate Card'!C9+G10*'⚙️ Rate Card'!C10+H10*'⚙️ Rate Card'!C11+I10*'⚙️ Rate Card'!C12+J10*'⚙️ Rate Card'!C13+K10*'⚙️ Rate Card'!C14+(D10/100)*'⚙️ Rate Card'!C8+L10*IF(OR(O10="N/A",O10="None",O10=""),0,IF(O10="High",'⚙️ Rate Card'!C20,IF(O10="Medium",'⚙️ Rate Card'!C19,'⚙️ Rate Card'!C18)))+M10*IF(OR(P10="Decommission",P10=""),'⚙️ Rate Card'!C29,IF(P10="EC2 (Lift & Shift)",'⚙️ Rate Card'!C25,IF(P10="AWS QuickSight",'⚙️ Rate Card'!C27,IF(P10="Power BI",'⚙️ Rate Card'!C28,IF(P10="Custom Reporting Solution",'⚙️ Rate Card'!C26,0)))))+IF(B10="",0,'⚙️ Rate Card'!C33+(D10/100)*'⚙️ Rate Card'!C34))*'⚙️ Rate Card'!C36)*(1-'📊 Dashboard'!C10/100)) -> 0 | T10: =IF(B10="",0,S10*(1+'📊 Dashboard'!C14/100)) -> 0 | U10: =IF(B10="",0,((D10/100)*'⚙️ Rate Card'!C7+F10*'⚙️ Rate Card'!C9+G10*'⚙️ Rate Card'!C10+H10*'⚙️ Rate Card'!C11+I10*'⚙️ Rate Card'!C12+J10*'⚙️ Rate Card'!C13+K10*'⚙️ Rate Card'!C14+(D10/100)*'⚙️ Rate Card'!C8+L10*IF(OR(O10="N/A",O10="None",O10=""),0,IF(O10="High",'⚙️ Rate Card'!C20,IF(O10="Medium",'⚙️ Rate Card'!C19,'⚙️ Rate Card'!C18)))+M10*IF(OR(P10="Decommission",P10=""),'⚙️ Rate Card'!C29,IF(P10="EC2 (Lift & Shift)",'⚙️ Rate Card'!C25,IF(P10="AWS QuickSight",'⚙️ Rate Card'!C27,IF(P10="Power BI",'⚙️ Rate Card'!C28,IF(P10="Custom Reporting Solution",'⚙️ Rate Card'!C26,0)))))+IF(B10="",0,'⚙️ Rate Card'!C33+(D10/100)*'⚙️ Rate Card'!C34))*'⚙️ Rate Card'!C37) -> 0 | V10: =IF(B10="",0,(D10/100)*'⚙️ Rate Card'!C7+F10*'⚙️ Rate Card'!C9+G10*'⚙️ Rate Card'!C10+H10*'⚙️ Rate Card'!C11+I10*'⚙️ Rate Card'!C12+J10*'⚙️ Rate Card'!C13+K10*'⚙️ Rate Card'!C14+(D10/100)*'⚙️ Rate Card'!C8+(D10/100)*'⚙️ Rate Card'!C8) -> 0 | W10: =IF(B10="",0,L10*IF(OR(O10="N/A",O10="None",O10=""),0,IF(O10="High",'⚙️ Rate Card'!C20,IF(O10="Medium",'⚙️ Rate Card'!C19,'⚙️ Rate Card'!C18)))) -> 0 | X10: =IF(B10="",0,M10*IF(OR(P10="Decommission",P10=""),'⚙️ Rate Card'!C29,IF(P10="EC2 (Lift & Shift)",'⚙️ Rate Card'!C25,IF(P10="AWS QuickSight",'⚙️ Rate Card'!C27,IF(P10="Power BI",'⚙️ Rate Card'!C28,IF(P10="Custom Reporting Solution",'⚙️ Rate Card'!C26,0)))))) -> 0 | Y10: =IF(B10="",0,IF(B10="",0,'⚙️ Rate Card'!C33+(D10/100)*'⚙️ Rate Card'!C34)) -> 0 | Z10: =IF(B10="",0,((D10/100)*'⚙️ Rate Card'!C7+F10*'⚙️ Rate Card'!C9+G10*'⚙️ Rate Card'!C10+H10*'⚙️ Rate Card'!C11+I10*'⚙️ Rate Card'!C12+J10*'⚙️ Rate Card'!C13+K10*'⚙️ Rate Card'!C14+(D10/100)*'⚙️ Rate Card'!C8+L10*IF(OR(O10="N/A",O10="None",O10=""),0,IF(O10="High",'⚙️ Rate Card'!C20,IF(O10="Medium",'⚙️ Rate Card'!C19,'⚙️ Rate Card'!C18)))+M10*IF(OR(P10="Decommission",P10=""),'⚙️ Rate Card'!C29,IF(P10="EC2 (Lift & Shift)",'⚙️ Rate Card'!C25,IF(P10="AWS QuickSight",'⚙️ Rate Card'!C27,IF(P10="Power BI",'⚙️ Rate Card'!C28,IF(P10="Custom Reporting Solution",'⚙️ Rate Card'!C26,0)))))+IF(B10="",0,'⚙️ Rate Card'!C33+(D10/100)*'⚙️ Rate Card'!C34))*'⚙️ Rate Card'!C35) -> 0 | AA10: =IF(B10="",0,((D10/100)*'⚙️ Rate Card'!C7+F10*'⚙️ Rate Card'!C9+G10*'⚙️ Rate Card'!C10+H10*'⚙️ Rate Card'!C11+I10*'⚙️ Rate Card'!C12+J10*'⚙️ Rate Card'!C13+K10*'⚙️ Rate Card'!C14+(D10/100)*'⚙️ Rate Card'!C8+L10*IF(OR(O10="N/A",O10="None",O10=""),0,IF(O10="High",'⚙️ Rate Card'!C20,IF(O10="Medium",'⚙️ Rate Card'!C19,'⚙️ Rate Card'!C18)))+M10*IF(OR(P10="Decommission",P10=""),'⚙️ Rate Card'!C29,IF(P10="EC2 (Lift & Shift)",'⚙️ Rate Card'!C25,IF(P10="AWS QuickSight",'⚙️ Rate Card'!C27,IF(P10="Power BI",'⚙️ Rate Card'!C28,IF(P10="Custom Reporting Solution",'⚙️ Rate Card'!C26,0)))))+IF(B10="",0,'⚙️ Rate Card'!C33+(D10/100)*'⚙️ Rate Card'!C34))*'⚙️ Rate Card'!C36) -> 0 | AB10: ='✏️ SME Input'!T11 -> 0 | AC10: =IF(B10="",0,AB10*0.75) -> 0 | AD10: =IF(B10="",0,AB10*0.75) -> 0 | AE10: =IF(B10="",0,AB10*0.75) -> 0 | AF10: =IF(B10="",0,AB10*2.25) -> 0 | AG10: =IF(B10="",0,((D10/100)*'⚙️ Rate Card'!C7+F10*'⚙️ Rate Card'!C9+G10*'⚙️ Rate Card'!C10+H10*'⚙️ Rate Card'!C11+I10*'⚙️ Rate Card'!C12+J10*'⚙️ Rate Card'!C13+K10*'⚙️ Rate Card'!C14+(D10/100)*'⚙️ Rate Card'!C8)*0.4) -> 0 | AH10: =IF(B10="",0,((D10/100)*'⚙️ Rate Card'!C7+F10*'⚙️ Rate Card'!C9+G10*'⚙️ Rate Card'!C10+H10*'⚙️ Rate Card'!C11+I10*'⚙️ Rate Card'!C12+J10*'⚙️ Rate Card'!C13+K10*'⚙️ Rate Card'!C14+(D10/100)*'⚙️ Rate Card'!C8)*0.4) -> 0 | AI10: =IF(B10="",0,((D10/100)*'⚙️ Rate Card'!C7+F10*'⚙️ Rate Card'!C9+G10*'⚙️ Rate Card'!C10+H10*'⚙️ Rate Card'!C11+I10*'⚙️ Rate Card'!C12+J10*'⚙️ Rate Card'!C13+K10*'⚙️ Rate Card'!C14+(D10/100)*'⚙️ Rate Card'!C8)*0.2) -> 0 | AJ10: =IF(B10="",0,(L10*IF(OR(O10="N/A",O10="None",O10=""),0,IF(O10="High",'⚙️ Rate Card'!C20,IF(O10="Medium",'⚙️ Rate Card'!C19,'⚙️ Rate Card'!C18))))*0.5) -> 0 | AK10: =IF(B10="",0,(L10*IF(OR(O10="N/A",O10="None",O10=""),0,IF(O10="High",'⚙️ Rate Card'!C20,IF(O10="Medium",'⚙️ Rate Card'!C19,'⚙️ Rate Card'!C18))))*0.35) -> 0 | AL10: =IF(B10="",0,(L10*IF(OR(O10="N/A",O10="None",O10=""),0,IF(O10="High",'⚙️ Rate Card'!C20,IF(O10="Medium",'⚙️ Rate Card'!C19,'⚙️ Rate Card'!C18))))*0.15) -> 0 | AM10: =IF(B10="",0,AG10+AJ10+(M10*IF(OR(P10="Decommission",P10=""),'⚙️ Rate Card'!C29,IF(P10="EC2 (Lift & Shift)",'⚙️ Rate Card'!C25,IF(P10="AWS QuickSight",'⚙️ Rate Card'!C27,IF(P10="Power BI",'⚙️ Rate Card'!C28,IF(P10="Custom Reporting Solution",'⚙️ Rate Card'!C26,0))))))*0.4+(IF(B10="",0,'⚙️ Rate Card'!C33+(D10/100)*'⚙️ Rate Card'!C34))*0.4+AC10+(((D10/100)*'⚙️ Rate Card'!C7+F10*'⚙️ Rate Card'!C9+G10*'⚙️ Rate Card'!C10+H10*'⚙️ Rate Card'!C11+I10*'⚙️ Rate Card'!C12+J10*'⚙️ Rate Card'!C13+K10*'⚙️ Rate Card'!C14+(D10/100)*'⚙️ Rate Card'!C8+L10*IF(OR(O10="N/A",O10="None",O10=""),0,IF(O10="High",'⚙️ Rate Card'!C20,IF(O10="Medium",'⚙️ Rate Card'!C19,'⚙️ Rate Card'!C18)))+M10*IF(OR(P10="Decommission",P10=""),'⚙️ Rate Card'!C29,IF(P10="EC2 (Lift & Shift)",'⚙️ Rate Card'!C25,IF(P10="AWS QuickSight",'⚙️ Rate Card'!C27,IF(P10="Power BI",'⚙️ Rate Card'!C28,IF(P10="Custom Reporting Solution",'⚙️ Rate Card'!C26,0)))))+IF(B10="",0,'⚙️ Rate Card'!C33+(D10/100)*'⚙️ Rate Card'!C34)))*'⚙️ Rate Card'!C35*0.4+(((D10/100)*'⚙️ Rate Card'!C7+F10*'⚙️ Rate Card'!C9+G10*'⚙️ Rate Card'!C10+H10*'⚙️ Rate Card'!C11+I10*'⚙️ Rate Card'!C12+J10*'⚙️ Rate Card'!C13+K10*'⚙️ Rate Card'!C14+(D10/100)*'⚙️ Rate Card'!C8+L10*IF(OR(O10="N/A",O10="None",O10=""),0,IF(O10="High",'⚙️ Rate Card'!C20,IF(O10="Medium",'⚙️ Rate Card'!C19,'⚙️ Rate Card'!C18)))+M10*IF(OR(P10="Decommission",P10=""),'⚙️ Rate Card'!C29,IF(P10="EC2 (Lift & Shift)",'⚙️ Rate Card'!C25,IF(P10="AWS QuickSight",'⚙️ Rate Card'!C27,IF(P10="Power BI",'⚙️ Rate Card'!C28,IF(P10="Custom Reporting Solution",'⚙️ Rate Card'!C26,0)))))+IF(B10="",0,'⚙️ Rate Card'!C33+(D10/100)*'⚙️ Rate Card'!C34)))*'⚙️ Rate Card'!C36*0.4+(((D10/100)*'⚙️ Rate Card'!C7+F10*'⚙️ Rate Card'!C9+G10*'⚙️ Rate Card'!C10+H10*'⚙️ Rate Card'!C11+I10*'⚙️ Rate Card'!C12+J10*'⚙️ Rate Card'!C13+K10*'⚙️ Rate Card'!C14+(D10/100)*'⚙️ Rate Card'!C8+L10*IF(OR(O10="N/A",O10="None",O10=""),0,IF(O10="High",'⚙️ Rate Card'!C20,IF(O10="Medium",'⚙️ Rate Card'!C19,'⚙️ Rate Card'!C18)))+M10*IF(OR(P10="Decommission",P10=""),'⚙️ Rate Card'!C29,IF(P10="EC2 (Lift & Shift)",'⚙️ Rate Card'!C25,IF(P10="AWS QuickSight",'⚙️ Rate Card'!C27,IF(P10="Power BI",'⚙️ Rate Card'!C28,IF(P10="Custom Reporting Solution",'⚙️ Rate Card'!C26,0)))))+IF(B10="",0,'⚙️ Rate Card'!C33+(D10/100)*'⚙️ Rate Card'!C34)))*'⚙️ Rate Card'!C37*0.4) -> 0 | AN10: =IF(B10="",0,AH10+AK10+(M10*IF(OR(P10="Decommission",P10=""),'⚙️ Rate Card'!C29,IF(P10="EC2 (Lift & Shift)",'⚙️ Rate Card'!C25,IF(P10="AWS QuickSight",'⚙️ Rate Card'!C27,IF(P10="Power BI",'⚙️ Rate Card'!C28,IF(P10="Custom Reporting Solution",'⚙️ Rate Card'!C26,0))))))*0.4+(IF(B10="",0,'⚙️ Rate Card'!C33+(D10/100)*'⚙️ Rate Card'!C34))*0.4+AD10+(((D10/100)*'⚙️ Rate Card'!C7+F10*'⚙️ Rate Card'!C9+G10*'⚙️ Rate Card'!C10+H10*'⚙️ Rate Card'!C11+I10*'⚙️ Rate Card'!C12+J10*'⚙️ Rate Card'!C13+K10*'⚙️ Rate Card'!C14+(D10/100)*'⚙️ Rate Card'!C8+L10*IF(OR(O10="N/A",O10="None",O10=""),0,IF(O10="High",'⚙️ Rate Card'!C20,IF(O10="Medium",'⚙️ Rate Card'!C19,'⚙️ Rate Card'!C18)))+M10*IF(OR(P10="Decommission",P10=""),'⚙️ Rate Card'!C29,IF(P10="EC2 (Lift & Shift)",'⚙️ Rate Card'!C25,IF(P10="AWS QuickSight",'⚙️ Rate Card'!C27,IF(P10="Power BI",'⚙️ Rate Card'!C28,IF(P10="Custom Reporting Solution",'⚙️ Rate Card'!C26,0)))))+IF(B10="",0,'⚙️ Rate Card'!C33+(D10/100)*'⚙️ Rate Card'!C34)))*'⚙️ Rate Card'!C35*0.4+(((D10/100)*'⚙️ Rate Card'!C7+F10*'⚙️ Rate Card'!C9+G10*'⚙️ Rate Card'!C10+H10*'⚙️ Rate Card'!C11+I10*'⚙️ Rate Card'!C12+J10*'⚙️ Rate Card'!C13+K10*'⚙️ Rate Card'!C14+(D10/100)*'⚙️ Rate Card'!C8+L10*IF(OR(O10="N/A",O10="None",O10=""),0,IF(O10="High",'⚙️ Rate Card'!C20,IF(O10="Medium",'⚙️ Rate Card'!C19,'⚙️ Rate Card'!C18)))+M10*IF(OR(P10="Decommission",P10=""),'⚙️ Rate Card'!C29,IF(P10="EC2 (Lift & Shift)",'⚙️ Rate Card'!C25,IF(P10="AWS QuickSight",'⚙️ Rate Card'!C27,IF(P10="Power BI",'⚙️ Rate Card'!C28,IF(P10="Custom Reporting Solution",'⚙️ Rate Card'!C26,0)))))+IF(B10="",0,'⚙️ Rate Card'!C33+(D10/100)*'⚙️ Rate Card'!C34)))*'⚙️ Rate Card'!C36*0.4+(((D10/100)*'⚙️ Rate Card'!C7+F10*'⚙️ Rate Card'!C9+G10*'⚙️ Rate Card'!C10+H10*'⚙️ Rate Card'!C11+I10*'⚙️ Rate Card'!C12+J10*'⚙️ Rate Card'!C13+K10*'⚙️ Rate Card'!C14+(D10/100)*'⚙️ Rate Card'!C8+L10*IF(OR(O10="N/A",O10="None",O10=""),0,IF(O10="High",'⚙️ Rate Card'!C20,IF(O10="Medium",'⚙️ Rate Card'!C19,'⚙️ Rate Card'!C18)))+M10*IF(OR(P10="Decommission",P10=""),'⚙️ Rate Card'!C29,IF(P10="EC2 (Lift & Shift)",'⚙️ Rate Card'!C25,IF(P10="AWS QuickSight",'⚙️ Rate Card'!C27,IF(P10="Power BI",'⚙️ Rate Card'!C28,IF(P10="Custom Reporting Solution",'⚙️ Rate Card'!C26,0)))))+IF(B10="",0,'⚙️ Rate Card'!C33+(D10/100)*'⚙️ Rate Card'!C34)))*'⚙️ Rate Card'!C37*0.4) -> 0 | AO10: =IF(B10="",0,AI10+AL10+(M10*IF(OR(P10="Decommission",P10=""),'⚙️ Rate Card'!C29,IF(P10="EC2 (Lift & Shift)",'⚙️ Rate Card'!C25,IF(P10="AWS QuickSight",'⚙️ Rate Card'!C27,IF(P10="Power BI",'⚙️ Rate Card'!C28,IF(P10="Custom Reporting Solution",'⚙️ Rate Card'!C26,0))))))*0.2+(IF(B10="",0,'⚙️ Rate Card'!C33+(D10/100)*'⚙️ Rate Card'!C34))*0.2+AE10+(((D10/100)*'⚙️ Rate Card'!C7+F10*'⚙️ Rate Card'!C9+G10*'⚙️ Rate Card'!C10+H10*'⚙️ Rate Card'!C11+I10*'⚙️ Rate Card'!C12+J10*'⚙️ Rate Card'!C13+K10*'⚙️ Rate Card'!C14+(D10/100)*'⚙️ Rate Card'!C8+L10*IF(OR(O10="N/A",O10="None",O10=""),0,IF(O10="High",'⚙️ Rate Card'!C20,IF(O10="Medium",'⚙️ Rate Card'!C19,'⚙️ Rate Card'!C18)))+M10*IF(OR(P10="Decommission",P10=""),'⚙️ Rate Card'!C29,IF(P10="EC2 (Lift & Shift)",'⚙️ Rate Card'!C25,IF(P10="AWS QuickSight",'⚙️ Rate Card'!C27,IF(P10="Power BI",'⚙️ Rate Card'!C28,IF(P10="Custom Reporting Solution",'⚙️ Rate Card'!C26,0)))))+IF(B10="",0,'⚙️ Rate Card'!C33+(D10/100)*'⚙️ Rate Card'!C34)))*'⚙️ Rate Card'!C35*0.2+(((D10/100)*'⚙️ Rate Card'!C7+F10*'⚙️ Rate Card'!C9+G10*'⚙️ Rate Card'!C10+H10*'⚙️ Rate Card'!C11+I10*'⚙️ Rate Card'!C12+J10*'⚙️ Rate Card'!C13+K10*'⚙️ Rate Card'!C14+(D10/100)*'⚙️ Rate Card'!C8+L10*IF(OR(O10="N/A",O10="None",O10=""),0,IF(O10="High",'⚙️ Rate Card'!C20,IF(O10="Medium",'⚙️ Rate Card'!C19,'⚙️ Rate Card'!C18)))+M10*IF(OR(P10="Decommission",P10=""),'⚙️ Rate Card'!C29,IF(P10="EC2 (Lift & Shift)",'⚙️ Rate Card'!C25,IF(P10="AWS QuickSight",'⚙️ Rate Card'!C27,IF(P10="Power BI",'⚙️ Rate Card'!C28,IF(P10="Custom Reporting Solution",'⚙️ Rate Card'!C26,0)))))+IF(B10="",0,'⚙️ Rate Card'!C33+(D10/100)*'⚙️ Rate Card'!C34)))*'⚙️ Rate Card'!C36*0.2+(((D10/100)*'⚙️ Rate Card'!C7+F10*'⚙️ Rate Card'!C9+G10*'⚙️ Rate Card'!C10+H10*'⚙️ Rate Card'!C11+I10*'⚙️ Rate Card'!C12+J10*'⚙️ Rate Card'!C13+K10*'⚙️ Rate Card'!C14+(D10/100)*'⚙️ Rate Card'!C8+L10*IF(OR(O10="N/A",O10="None",O10=""),0,IF(O10="High",'⚙️ Rate Card'!C20,IF(O10="Medium",'⚙️ Rate Card'!C19,'⚙️ Rate Card'!C18)))+M10*IF(OR(P10="Decommission",P10=""),'⚙️ Rate Card'!C29,IF(P10="EC2 (Lift & Shift)",'⚙️ Rate Card'!C25,IF(P10="AWS QuickSight",'⚙️ Rate Card'!C27,IF(P10="Power BI",'⚙️ Rate Card'!C28,IF(P10="Custom Reporting Solution",'⚙️ Rate Card'!C26,0)))))+IF(B10="",0,'⚙️ Rate Card'!C33+(D10/100)*'⚙️ Rate Card'!C34)))*'⚙️ Rate Card'!C37*0.2) -> 0 | AP10: ='✏️ SME Input'!B11 -> 0 | AQ10: ='✏️ SME Input'!C11 -> 0 | AR10: ='✏️ SME Input'!D11 -> 0
