Workbook

Sheet ✏️ SME Input
B5: 📋 INSTRUCTIONS: Fill in ORANGE cells only for your application. Grey cells are locked (auto-calculated or reference only). Dropdown cells have a pick-list — click the cell to see options. Contact the Migration PMO if you have questions.
B6: Application Name | C6: Wave / Release | D6: DB Size (GB) | E6: No. of Tables | F6: No. of Stored Procs | G6: No. of Views | H6: No. of Triggers | I6: SQL Agent Jobs | J6: Linked Servers | K6: CLR Objects | L6: SSIS Packages | M6: SSRS Reports | N6: Informatica Workflows/Jobs (No workflow change — enter count) | O6: SSIS Complexity | P6: SSRS Strategy | Q6: SME Notes / Risks | R6: Informatica Job Count | S6: Replication Articles (Trans+Merge) | T6: Snapshot Publications | U6: Replication Type
B7: Reference | C7: ⬆ ENTER | D7: ⬆ ENTER | E7: ⬆ ENTER | F7: ⬆ ENTER | G7: ⬆ ENTER | H7: ⬆ ENTER | I7: ⬆ ENTER | J7: ⬆ ENTER | K7: ⬆ ENTER | L7: ⬆ ENTER | M7: ⬆ ENTER | N7: ⬆ ENTER count | O7: ⬆ ENTER | P7: ⬆ ENTER | Q7: ⬆ ENTER | R7: ⬆ ENTER | S7: ⬆ ENTER | T7: ⬆ ENTER | U7: ⬆ Dropdown
B8: Order Management System | C8: Wave 2 | D8: 450 | E8: 120 | F8: 85 | G8: 45 | H8: 12 | I8: 8 | J8: 2 | K8: 3 | L8: 18 | M8: 22 | N8: 5 | O8: High | P8: EC2 (Lift & Shift) | R8: 5 | S8: 8 | T8: 0 | U8: Transactional
B9: Billing Engine | C9: Wave 2 | D9: 820 | E9: 200 | F9: 140 | G9: 60 | H9: 18 | I9: 15 | J9: 4 | K9: 6 | L9: 32 | M9: 35 | N9: 12 | O9: High | P9: EC2 (Lift & Shift) | R9: 12 | S9: 15 | T9: 2 | U9: Transactional
B10: Customer Portal DB | C10: Wave 1 | D10: 180 | E10: 80 | F10: 45 | G10: 30 | H10: 5 | I10: 3 | J10: 0 | K10: 0 | L10: 8 | M10: 10 | N10: 0 | O10: Medium | P10: AWS QuickSight | R10: 0 | S10: 0 | T10: 0 | U10: None
B11: Provisioning System | C11: Wave 2 | D11: 650 | E11: 150 | F11: 110 | G11: 55 | H11: 14 | I11: 10 | J11: 3 | K11: 2 | L11: 24 | M11: 18 | N11: 8 | O11: High | P11: EC2 (Lift & Shift) | R11: 8 | S11: 6 | T11: 0 | U11: Transactional
B12: Revenue Assurance | C12: Wave 4 | D12: 1200 | E12: 280 | F12: 190 | G12: 90 | H12: 22 | I12: 20 | J12: 6 | K12: 8 | L12: 40 | M12: 50 | N12: 20 | O12: High | P12: EC2 (Lift & Shift) | R12: 20 | S12: 20 | T12: 3 | U12: Mixed
B13: Fraud Management | C13: Wave 2 | D13: 340 | E13: 95 | F13: 65 | G13: 35 | H13: 8 | I13: 6 | J13: 1 | K13: 4 | L13: 15 | M13: 12 | N13: 3 | O13: Medium | P13: Power BI | R13: 3 | S13: 4 | T13: 0 | U13: Transactional
B14: Network Inventory DB | C14: Wave 2 | D14: 560 | E14: 130 | F14: 95 | G14: 48 | H14: 10 | I14: 9 | J14: 2 | K14: 1 | L14: 20 | M14: 16 | N14: 6 | O14: Medium | P14: AWS QuickSight | R14: 6 | S14: 5 | T14: 0 | U14: Transactional
B15: CRM Integration DB | C15: Wave 1 | D15: 220 | E15: 75 | F15: 50 | G15: 28 | H15: 6 | I15: 4 | J15: 0 | K15: 0 | L15: 10 | M15: 8 | N15: 2 | O15: Medium | P15: AWS QuickSight | R15: 2 | S15: 2 | T15: 0 | U15: None
B16: Product Catalogue | C16: Wave 1 | D16: 90 | E16: 45 | F16: 30 | G16: 20 | H16: 3 | I16: 2 | J16: 0 | K16: 0 | L16: 4 | M16: 5 | N16: 0 | O16: Low | P16: AWS QuickSight | R16: 0 | S16: 0 | T16: 0 | U16: None
B17: Mediation Platform | C17: Wave 3 | D17: 780 | E17: 180 | F17: 125 | G17: 65 | H17: 16 | I17: 12 | J17: 3 | K17: 5 | L17: 28 | M17: 20 | N17: 10 | O17: High | P17: EC2 (Lift & Shift) | R17: 10 | S17: 10 | T17: 0 | U17: Transactional
B18: Interconnect Billing | C18: Wave 2 | D18: 420 | E18: 110 | F18: 80 | G18: 40 | H18: 9 | I18: 7 | J18: 2 | K18: 2 | L18: 16 | M18: 14 | N18: 4 | O18: Medium | P18: EC2 (Lift & Shift) | R18: 4 | S18: 4 | T18: 0 | U18: Transactional
B19: Roaming Settlement | C19: Wave 2 | D19: 390 | E19: 100 | F19: 72 | G19: 38 | H19: 8 | I19: 6 | J19: 1 | K19: 3 | L19: 14 | M19: 12 | N19: 5 | O19: Medium | P19: EC2 (Lift & Shift) | R19: 5 | S19: 3 | T19: 0 | U19: Transactional
... B36: MDM Master Data DB | C36: Wave 4 | D36: 520 | E36: 140 | F36: 98 | G36: 52 | H36: 12 | I36: 9 | J36: 3 | K36: 1 | L36: 18 | M36: 22 | N36: 7 | O36: High | P36: EC2 (Lift & Shift) | R36: 7 | S36: 8 | T36: 1 | U36: Transactional
B37: TOTALS (auto) | C37: =SUM(C8:C36) -> 0 | D37: =SUM(D8:D36) -> 13340 | E37: =SUM(E8:E36) -> 3483 | F37: =SUM(F8:F36) -> 2207 | G37: =SUM(G8:G36) -> 1292 | H37: =SUM(H8:H36) -> 259 | I37: =SUM(I8:I36) -> 217 | J37: =SUM(J8:J36) -> 45 | ... N37: =SUM(N8:N36) -> 121 | R37: =SUM(R8:R36) -> 121 | S37: =SUM(S8:S36) -> 122 | T37: =SUM(T8:T36) -> 8

Sheet 📋 App Effort Detail
B4: Formulas auto-calculate from SME Input sheet values. Orange = SME editable input. Green = calculated output. Hours = Days × 8. AI saving applied per role. Contingency = AI-adj × (1 + buffer%).
B5: APP IDENTITY | D5: DATABASE PROFILE | I5: SQL OBJECT INVENTORY | O5: ETL & REPORTING | R5: EFFORT TOTALS (hours) | AB5: INFORMATICA EFFORT (hrs) | AG5: ENVIRONMENT BREAKDOWN — Data & ETL (hrs) | AM5: TOTAL BY ENV (hrs)
B6: Application Name | C6: Tier (Auto) | D6: DB Size (GB) | E6: Tables | F6: Stored Procs | G6: Views | H6: Triggers | I6: SQL Agent Jobs | J6: Linked Servers | K6: CLR Objects | L6: SSIS Packages | M6: SSRS Reports | N6: Informatica Workflows/Jobs (No workflow change — count for JDBC) | O6: SSIS Complexity | P6: SSRS Strategy | Q6: Wave | R6: Gross Hours | S6: AI-Adj Hours | T6: Hours w/ Contingency | AB6: Informatica Job Count | AC6: Inform. Dev hrs | AD6: Inform. Test hrs | AE6: Inform. Prod hrs | AF6: Inform. Total hrs | AG6: Data Dev hrs | AH6: Data Test hrs | AI6: Data Prod hrs | AJ6: ETL Dev hrs | AK6: ETL Test hrs | AL6: ETL Prod hrs | AM6: Total Dev hrs | AN6: Total Test hrs | AO6: Total Prod hrs
B7: Label/Formula | C7: Label/Formula | D7: ⬆ Input | E7: ⬆ Input | F7: ⬆ Input | G7: ⬆ Input | H7: ⬆ Input | I7: ⬆ Input | J7: ⬆ Input | K7: ⬆ Input | L7: ⬆ Input | M7: ⬆ Input | N7: ⬆ Input | O7: ⬆ Input | P7: ⬆ Input | Q7: ⬆ Input | R7: Formula | S7: Formula | T7: Formula | AB7: Ref SME | AC7: Formula | AD7: Formula | AE7: Formula | AF7: Formula | AG7: Formula | AH7: Formula | AI7: Formula | AJ7: Formula | AK7: Formula | AL7: Formula | AM7: Formula | AN7: Formula | AO7: Formula
B8: ='✏️ SME Input'!B8 -> Order Management System | C8: =IF(D8>1000,"T3 Complex",IF(D8>500,"T2 Moderate","T1 Simple")) -> T1 Simple | D8: ='✏️ SME Input'!D8 -> 450 | E8: ='✏️ SME Input'!E8 -> 120 | F8: ='✏️ SME Input'!F8 -> 85 | G8: ='✏️ SME Input'!G8 -> 45 | H8: ='✏️ SME Input'!H8 -> 12 | I8: ='✏️ SME Input'!I8 -> 8 | J8: ='✏️ SME Input'!J8 -> 2 | K8: ='✏️ SME Input'!K8 -> 3 | ... P8: ='✏️ SME Input'!P8 -> EC2 (Lift & Shift) | Q8: ='✏️ SME Input'!C8 -> Wave 2 | R8: =((((D8/100)*0.5+F8*0.5+G8*0.2+H8*0.8+I8*1+J8*3+K8*5+(D8/100)*0.3)*8+(L8*IF(O8="High",2,IF(O8="Medium",1,0.5)))*8+(M8*IF(P8="EC2 (Lift & Shift)",0.2,IF(P8="AWS QuickSight",1.5,IF(P8="Power BI",1,0.5))))*8+(10+(D8/100)*0.5)*8))*0.08+(((D8/100)*0.5+F8*0.5+G8*0.2+H8*0.8+I8*1+J8*3+K8*5+(D8/100)*0.3)*8+(D8/100)*0.3*8)+((L8*IF(O8="High",2,IF(O8="Medium",1,0.5)))*8)+((M8*IF(P8="EC2 (Lift & Shift)",0.2,IF(P8="AWS QuickSight",1.5,IF(P8="Power BI",1,0.5))))*8)+((10+(D8/100)*0.5)*8)+((((D8/100)*0.5+F8*0.5+G8*0.2+H8*0.8+I8*1+J8*3+K8*5+(D8/100)*0.3)*8+(L8*IF(O8="High",2,IF(O8="Medium",1,0.5)))*8+(M8*IF(P8="EC2 (Lift & Shift)",0.2,IF(P8="AWS QuickSight",1.5,IF(P8="Power BI",1,0.5))))*8+(10+(D8/100)*0.5)*8))*0.28+((((D8/100)*0.5+F8*0.5+G8*0.2+H8*0.8+I8*1+J8*3+K8*5+(D8/100)*0.3)*8+(L8*IF(O8="High",2,IF(O8="Medium",1,0.5)))*8+(M8*IF(P8="EC2 (Lift & Shift)",0.2,IF(P8="AWS QuickSight",1.5,IF(P8="Power BI",1,0.5))))*8+(10+(D8/100)*0.5)*8))*0.12 -> 1743.584 | S8: =((((D8/100)*0.5+F8*0.5+G8*0.2+H8*0.8+I8*1+J8*3+K8*5+(D8/100)*0.3)*8+(L8*IF(O8="High",2,IF(O8="Medium",1,0.5)))*8+(M8*IF(P8="EC2 (Lift & Shift)",0.2,IF(P8="AWS QuickSight",1.5,IF(P8="Power BI",1,0.5))))*8+(10+(D8/100)*0.5)*8)*0.08)*(1-'📊 Dashboard'!C10/100)+((((D8/100)*0.5+F8*0.5+G8*0.2+H8*0.8+I8*1+J8*3+K8*5+(D8/100)*0.3)*8+(D8/100)*0.3*8))*(1-'📊 Dashboard'!C10/100)+((L8*IF(O8="High",2,IF(O8="Medium",1,0.5)))*8)*(1-'📊 Dashboard'!C11/100)+((M8*IF(P8="EC2 (Lift & Shift)",0.2,IF(P8="AWS QuickSight",1.5,IF(P8="Power BI",1,0.5))))*8)*(1-'📊 Dashboard'!C12/100)+((10+(D8/100)*0.5)*8)*(1-'📊 Dashboard'!C10/100)+((((D8/100)*0.5+F8*0.5+G8*0.2+H8*0.8+I8*1+J8*3+K8*5+(D8/100)*0.3)*8+(L8*IF(O8="High",2,IF(O8="Medium",1,0.5)))*8+(M8*IF(P8="EC2 (Lift & Shift)",0.2,IF(P8="AWS QuickSight",1.5,IF(P8="Power BI",1,0.5))))*8+(10+(D8/100)*0.5)*8)*0.28)*(1-'📊 Dashboard'!C13/100)+((((D8/100)*0.5+F8*0.5+G8*0.2+H8*0.8+I8*1+J8*3+K8*5+(D8/100)*0.3)*8+(L8*IF(O8="High",2,IF(O8="Medium",1,0.5)))*8+(M8*IF(P8="EC2 (Lift & Shift)",0.2,IF(P8="AWS QuickSight",1.5,IF(P8="Power BI",1,0.5))))*8+(10+(D8/100)*0.5)*8)*0.12)*(1-'📊 Dashboard'!C10/100) -> 1271.2112 | T8: =S8*(1+'📊 Dashboard'!C14/100) -> 1461.8929 | U8: =(((D8/100)*0.5+F8*0.5+G8*0.2+H8*0.8+I8*1+J8*3+K8*5+(D8/100)*0.3)*8+(L8*IF(O8="High",2,IF(O8="Medium",1,0.5)))*8+(M8*IF(P8="EC2 (Lift & Shift)",0.2,IF(P8="AWS QuickSight",1.5,IF(P8="Power BI",1,0.5))))*8+(10+(D8/100)*0.5)*8)*0.08 -> 93.664 | V8: =((D8/100)*0.5+F8*0.5+G8*0.2+H8*0.8+I8*1+J8*3+K8*5+(D8/100)*0.3)*8+(D8/100)*0.3*8 -> 760.4 | W8: =(L8*IF(O8="High",2,IF(O8="Medium",1,0.5)))*8 -> 288 | X8: =(M8*IF(P8="EC2 (Lift & Shift)",0.2,IF(P8="AWS QuickSight",1.5,IF(P8="Power BI",1,0.5))))*8 -> 35.2 | Y8: =(10+(D8/100)*0.5)*8 -> 98 | Z8: =(((D8/100)*0.5+F8*0.5+G8*0.2+H8*0.8+I8*1+J8*3+K8*5+(D8/100)*0.3)*8+(L8*IF(O8="High",2,IF(O8="Medium",1,0.5)))*8+(M8*IF(P8="EC2 (Lift & Shift)",0.2,IF(P8="AWS QuickSight",1.5,IF(P8="Power BI",1,0.5))))*8+(10+(D8/100)*0.5)*8)*0.28 -> 327.824 | AA8: =(((D8/100)*0.5+F8*0.5+G8*0.2+H8*0.8+I8*1+J8*3+K8*5+(D8/100)*0.3)*8+(L8*IF(O8="High",2,IF(O8="Medium",1,0.5)))*8+(M8*IF(P8="EC2 (Lift & Shift)",0.2,IF(P8="AWS QuickSight",1.5,IF(P8="Power BI",1,0.5))))*8+(10+(D8/100)*0.5)*8)*0.12 -> 140.496 | AB8: ='✏️ SME Input'!R8 -> 5 | AC8: =AB8*0.75 -> 3.75 | AD8: =AB8*0.75 -> 3.75 | AE8: =AB8*0.75 -> 3.75 | AF8: =AB8*2.25 -> 11.25 | AG8: =(((D8/100)*0.5+F8*0.5+G8*0.2+H8*0.8+I8*1+J8*3+K8*5+(D8/100)*0.3)*8)*0.4 -> 299.84 | AH8: =(((D8/100)*0.5+F8*0.5+G8*0.2+H8*0.8+I8*1+J8*3+K8*5+(D8/100)*0.3)*8)*0.4 -> 299.84 | AI8: =(((D8/100)*0.5+F8*0.5+G8*0.2+H8*0.8+I8*1+J8*3+K8*5+(D8/100)*0.3)*8)*0.2 -> 149.92 | AJ8: =((L8*IF(O8="High",2,IF(O8="Medium",1,0.5)))*8)*0.5 -> 144 | AK8: =((L8*IF(O8="High",2,IF(O8="Medium",1,0.5)))*8)*0.35 -> 100.8 | AL8: =((L8*IF(O8="High",2,IF(O8="Medium",1,0.5)))*8)*0.15 -> 43.2 | AM8: =AG8+AJ8+((M8*IF(P8="EC2 (Lift & Shift)",0.2,IF(P8="AWS QuickSight",1.5,IF(P8="Power BI",1,0.5))))*8)*0.4+((10+(D8/100)*0.5)*8)*0.4+AC8+((((D8/100)*0.5+F8*0.5+G8*0.2+H8*0.8+I8*1+J8*3+K8*5+(D8/100)*0.3)*8+(L8*IF(O8="High",2,IF(O8="Medium",1,0.5)))*8+(M8*IF(P8="EC2 (Lift & Shift)",0.2,IF(P8="AWS QuickSight",1.5,IF(P8="Power BI",1,0.5))))*8+(10+(D8/100)*0.5)*8))*0.28*0.4+((((D8/100)*0.5+F8*0.5+G8*0.2+H8*0.8+I8*1+J8*3+K8*5+(D8/100)*0.3)*8+(L8*IF(O8="High",2,IF(O8="Medium",1,0.5)))*8+(M8*IF(P8="EC2 (Lift & Shift)",0.2,IF(P8="AWS QuickSight",1.5,IF(P8="Power BI",1,0.5))))*8+(10+(D8/100)*0.5)*8))*0.12*0.4+((((D8/100)*0.5+F8*0.5+G8*0.2+H8*0.8+I8*1+J8*3+K8*5+(D8/100)*0.3)*8+(L8*IF(O8="High",2,IF(O8="Medium",1,0.5)))*8+(M8*IF(P8="EC2 (Lift & Shift)",0.2,IF(P8="AWS QuickSight",1.5,IF(P8="Power BI",1,0.5))))*8+(10+(D8/100)*0.5)*8))*0.08*0.4 -> 725.6636 | AN8: =AH8+AK8+((M8*IF(P8="EC2 (Lift & Shift)",0.2,IF(P8="AWS QuickSight",1.5,IF(P8="Power BI",1,0.5))))*8)*0.4+((10+(D8/100)*0.5)*8)*0.4+AD8+((((D8/100)*0.5+F8*0.5+G8*0.2+H8*0.8+I8*1+J8*3+K8*5+(D8/100)*0.3)*8+(L8*IF(O8="High",2,IF(O8="Medium",1,0.5)))*8+(M8*IF(P8="EC2 (Lift & Shift)",0.2,IF(P8="AWS QuickSight",1.5,IF(P8="Power BI",1,0.5))))*8+(10+(D8/100)*0.5)*8))*0.28*0.4+((((D8/100)*0.5+F8*0.5+G8*0.2+H8*0.8+I8*1+J8*3+K8*5+(D8/100)*0.3)*8+(L8*IF(O8="High",2,IF(O8="Medium",1,0.5)))*8+(M8*IF(P8="EC2 (Lift & Shift)",0.2,IF(P8="AWS QuickSight",1.5,IF(P8="Power BI",1,0.5))))*8+(10+(D8/100)*0.5)*8))*0.12*0.4+((((D8/100)*0.5+F8*0.5+G8*0.2+H8*0.8+I8*1+J8*3+K8*5+(D8/100)*0.3)*8+(L8*IF(O8="High",2,IF(O8="Medium",1,0.5)))*8+(M8*IF(P8="EC2 (Lift & Shift)",0.2,IF(P8="AWS QuickSight",1.5,IF(P8="Power BI",1,0.5))))*8+(10+(D8/100)*0.5)*8))*0.08*0.4 -> 682.4636 | AO8: =AI8+AL8+((M8*IF(P8="EC2 (Lift & Shift)",0.2,IF(P8="AWS QuickSight",1.5,IF(P8="Power BI",1,0.5))))*8)*0.2+((10+(D8/100)*0.5)*8)*0.2+AE8+((((D8/100)*0.5+F8*0.5+G8*0.2+H8*0.8+I8*1+J8*3+K8*5+(D8/100)*0.3)*8+(L8*IF(O8="High",2,IF(O8="Medium",1,0.5)))*8+(M8*IF(P8="EC2 (Lift & Shift)",0.2,IF(P8="AWS QuickSight",1.5,IF(P8="Power BI",1,0.5))))*8+(10+(D8/100)*0.5)*8))*0.28*0.2+((((D8/100)*0.5+F8*0.5+G8*0.2+H8*0.8+I8*1+J8*3+K8*5+(D8/100)*0.3)*8+(L8*IF(O8="High",2,IF(O8="Medium",1,0.5)))*8+(M8*IF(P8="EC2 (Lift & Shift)",0.2,IF(P8="AWS QuickSight",1.5,IF(P8="Power BI",1,0.5))))*8+(10+(D8/100)*0.5)*8))*0.12*0.2+((((D8/100)*0.5+F8*0.5+G8*0.2+H8*0.8+I8*1+J8*3+K8*5+(D8/100)*0.3)*8+(L8*IF(O8="High",2,IF(O8="Medium",1,0.5)))*8+(M8*IF(P8="EC2 (Lift & Shift)",0.2,IF(P8="AWS QuickSight",1.5,IF(P8="Power BI",1,0.5))))*8+(10+(D8/100)*0.5)*8))*0.08*0.2 -> 335.9068 | AP8: ='✏️ SME Input'!S8 -> 8 | AQ8: ='✏️ SME Input'!T8 -> 0 | AR8: ='✏️ SME Input'!U8 -> Transactional
B9: ='✏️ SME Input'!B9 -> Billing Engine | C9: =IF(D9>1000,"T3 Complex",IF(D9>500,"T2 Moderate","T1 Simple")) -> T2 Moderate | D9: ='✏️ SME Input'!D9 -> 820 | E9: ='✏️ SME Input'!E9 -> 200 | F9: ='✏️ SME Input'!F9 -> 140 | G9: ='✏️ SME Input'!G9 -> 60 | H9: ='✏️ SME Input'!H9 -> 18 | I9: ='✏️ SME Input'!I9 -> 15 | J9: ='✏️ SME Input'!J9 -> 4 | K9: ='✏️ SME Input'!K9 -> 6 | ... P9: ='✏️ SME Input'!P9 -> EC2 (Lift & Shift) | Q9: ='✏️ SME Input'!C9 -> Wave 2 | R9: =((((D9/100)*0.5+F9*0.5+G9*0.2+H9*0.8+I9*1+J9*3+K9*5+(D9/100)*0.3)*8+(L9*IF(O9="High",2,IF(O9="Medium",1,0.5)))*8+(M9*IF(P9="EC2 (Lift & Shift)",0.2,IF(P9="AWS QuickSight",1.5,IF(P9="Power BI",1,0.5))))*8+(10+(D9/100)*0.5)*8))*0.08+(((D9/100)*0.5+F9*0.5+G9*0.2+H9*0.8+I9*1+J9*3+K9*5+(D9/100)*0.3)*8+(D9/100)*0.3*8)+((L9*IF(O9="High",2,IF(O9="Medium",1,0.5)))*8)+((M9*IF(P9="EC2 (Lift & Shift)",0.2,IF(P9="AWS QuickSight",1.5,IF(P9="Power BI",1,0.5))))*8)+((10+(D9/100)*0.5)*8)+((((D9/100)*0.5+F9*0.5+G9*0.2+H9*0.8+I9*1+J9*3+K9*5+(D9/100)*0.3)*8+(L9*IF(O9="High",2,IF(O9="Medium",1,0.5)))*8+(M9*IF(P9="EC2 (Lift & Shift)",0.2,IF(P9="AWS QuickSight",1.5,IF(P9="Power BI",1,0.5))))*8+(10+(D9/100)*0.5)*8))*0.28+((((D9/100)*0.5+F9*0.5+G9*0.2+H9*0.8+I9*1+J9*3+K9*5+(D9/100)*0.3)*8+(L9*IF(O9="High",2,IF(O9="Medium",1,0.5)))*8+(M9*IF(P9="EC2 (Lift & Shift)",0.2,IF(P9="AWS QuickSight",1.5,IF(P9="Power BI",1,0.5))))*8+(10+(D9/100)*0.5)*8))*0.12 -> 2921.1904 | S9: =((((D9/100)*0.5+F9*0.5+G9*0.2+H9*0.8+I9*1+J9*3+K9*5+(D9/100)*0.3)*8+(L9*IF(O9="High",2,IF(O9="Medium",1,0.5)))*8+(M9*IF(P9="EC2 (Lift & Shift)",0.2,IF(P9="AWS QuickSight",1.5,IF(P9="Power BI",1,0.5))))*8+(10+(D9/100)*0.5)*8)*0.08)*(1-'📊 Dashboard'!C10/100)+((((D9/100)*0.5+F9*0.5+G9*0.2+H9*0.8+I9*1+J9*3+K9*5+(D9/100)*0.3)*8+(D9/100)*0.3*8))*(1-'📊 Dashboard'!C10/100)+((L9*IF(O9="High",2,IF(O9="Medium",1,0.5)))*8)*(1-'📊 Dashboard'!C11/100)+((M9*IF(P9="EC2 (Lift & Shift)",0.2,IF(P9="AWS QuickSight",1.5,IF(P9="Power BI",1,0.5))))*8)*(1-'📊 Dashboard'!C12/100)+((10+(D9/100)*0.5)*8)*(1-'📊 Dashboard'!C10/100)+((((D9/100)*0.5+F9*0.5+G9*0.2+H9*0.8+I9*1+J9*3+K9*5+(D9/100)*0.3)*8+(L9*IF(O9="High",2,IF(O9="Medium",1,0.5)))*8+(M9*IF(P9="EC2 (Lift & Shift)",0.2,IF(P9="AWS QuickSight",1.5,IF(P9="Power BI",1,0.5))))*8+(10+(D9/100)*0.5)*8)*0.28)*(1-'📊 Dashboard'!C13/100)+((((D9/100)*0.5+F9*0.5+G9*0.2+H9*0.8+I9*1+J9*3+K9*5+(D9/100)*0.3)*8+(L9*IF(O9="High",2,IF(O9="Medium",1,0.5)))*8+(M9*IF(P9="EC2 (Lift & Shift)",0.2,IF(P9="AWS QuickSight",1.5,IF(P9="Power BI",1,0.5))))*8+(10+(D9/100)*0.5)*8)*0.12)*(1-'📊 Dashboard'!C10/100) -> 2130.9267 | T9: =S9*(1+'📊 Dashboard'!C14/100) -> 2450.5657 | U9: =(((D9/100)*0.5+F9*0.5+G9*0.2+H9*0.8+I9*1+J9*3+K9*5+(D9/100)*0.3)*8+(L9*IF(O9="High",2,IF(O9="Medium",1,0.5)))*8+(M9*IF(P9="EC2 (Lift & Shift)",0.2,IF(P9="AWS QuickSight",1.5,IF(P9="Power BI",1,0.5))))*8+(10+(D9/100)*0.5)*8)*0.08 -> 156.8384 | V9: =((D9/100)*0.5+F9*0.5+G9*0.2+H9*0.8+I9*1+J9*3+K9*5+(D9/100)*0.3)*8+(D9/100)*0.3*8 -> 1299.36 | W9: =(L9*IF(O9="High",2,IF(O9="Medium",1,0.5)))*8 -> 512 | X9: =(M9*IF(P9="EC2 (Lift & Shift)",0.2,IF(P9="AWS QuickSight",1.5,IF(P9="Power BI",1,0.5))))*8 -> 56 | Y9: =(10+(D9/100)*0.5)*8 -> 112.8 | Z9: =(((D9/100)*0.5+F9*0.5+G9*0.2+H9*0.8+I9*1+J9*3+K9*5+(D9/100)*0.3)*8+(L9*IF(O9="High",2,IF(O9="Medium",1,0.5)))*8+(M9*IF(P9="EC2 (Lift & Shift)",0.2,IF(P9="AWS QuickSight",1.5,IF(P9="Power BI",1,0.5))))*8+(10+(D9/100)*0.5)*8)*0.28 -> 548.9344 | AA9: =(((D9/100)*0.5+F9*0.5+G9*0.2+H9*0.8+I9*1+J9*3+K9*5+(D9/100)*0.3)*8+(L9*IF(O9="High",2,IF(O9="Medium",1,0.5)))*8+(M9*IF(P9="EC2 (Lift & Shift)",0.2,IF(P9="AWS QuickSight",1.5,IF(P9="Power BI",1,0.5))))*8+(10+(D9/100)*0.5)*8)*0.12 -> 235.2576 | AB9: ='✏️ SME Input'!R9 -> 12 | AC9: =AB9*0.75 -> 9 | AD9: =AB9*0.75 -> 9 | AE9: =AB9*0.75 -> 9 | AF9: =AB9*2.25 -> 27 | AG9: =(((D9/100)*0.5+F9*0.5+G9*0.2+H9*0.8+I9*1+J9*3+K9*5+(D9/100)*0.3)*8)*0.4 -> 511.872 | AH9: =(((D9/100)*0.5+F9*0.5+G9*0.2+H9*0.8+I9*1+J9*3+K9*5+(D9/100)*0.3)*8)*0.4 -> 511.872 | AI9: =(((D9/100)*0.5+F9*0.5+G9*0.2+H9*0.8+I9*1+J9*3+K9*5+(D9/100)*0.3)*8)*0.2 -> 255.936 | AJ9: =((L9*IF(O9="High",2,IF(O9="Medium",1,0.5)))*8)*0.5 -> 256 | AK9: =((L9*IF(O9="High",2,IF(O9="Medium",1,0.5)))*8)*0.35 -> 179.2 | AL9: =((L9*IF(O9="High",2,IF(O9="Medium",1,0.5)))*8)*0.15 -> 76.8 | AM9: =AG9+AJ9+((M9*IF(P9="EC2 (Lift & Shift)",0.2,IF(P9="AWS QuickSight",1.5,IF(P9="Power BI",1,0.5))))*8)*0.4+((10+(D9/100)*0.5)*8)*0.4+AC9+((((D9/100)*0.5+F9*0.5+G9*0.2+H9*0.8+I9*1+J9*3+K9*5+(D9/100)*0.3)*8+(L9*IF(O9="High",2,IF(O9="Medium",1,0.5)))*8+(M9*IF(P9="EC2 (Lift & Shift)",0.2,IF(P9="AWS QuickSight",1.5,IF(P9="Power BI",1,0.5))))*8+(10+(D9/100)*0.5)*8))*0.28*0.4+((((D9/100)*0.5+F9*0.5+G9*0.2+H9*0.8+I9*1+J9*3+K9*5+(D9/100)*0.3)*8+(L9*IF(O9="High",2,IF(O9="Medium",1,0.5)))*8+(M9*IF(P9="EC2 (Lift & Shift)",0.2,IF(P9="AWS QuickSight",1.5,IF(P9="Power BI",1,0.5))))*8+(10+(D9/100)*0.5)*8))*0.12*0.4+((((D9/100)*0.5+F9*0.5+G9*0.2+H9*0.8+I9*1+J9*3+K9*5+(D9/100)*0.3)*8+(L9*IF(O9="High",2,IF(O9="Medium",1,0.5)))*8+(M9*IF(P9="EC2 (Lift & Shift)",0.2,IF(P9="AWS QuickSight",1.5,IF(P9="Power BI",1,0.5))))*8+(10+(D9/100)*0.5)*8))*0.08*0.4 -> 1220.8042 | AN9: =AH9+AK9+((M9*IF(P9="EC2 (Lift & Shift)",0.2,IF(P9="AWS QuickSight",1.5,IF(P9="Power BI",1,0.5))))*8)*0.4+((10+(D9/100)*0.5)*8)*0.4+AD9+((((D9/100)*0.5+F9*0.5+G9*0.2+H9*0.8+I9*1+J9*3+K9*5+(D9/100)*0.3)*8+(L9*IF(O9="High",2,IF(O9="Medium",1,0.5)))*8+(M9*IF(P9="EC2 (Lift & Shift)",0.2,IF(P9="AWS QuickSight",1.5,IF(P9="Power BI",1,0.5))))*8+(10+(D9/100)*0.5)*8))*0.28*0.4+((((D9/100)*0.5+F9*0.5+G9*0.2+H9*0.8+I9*1+J9*3+K9*5+(D9/100)*0.3)*8+(L9*IF(O9="High",2,IF(O9="Medium",1,0.5)))*8+(M9*IF(P9="EC2 (Lift & Shift)",0.2,IF(P9="AWS QuickSight",1.5,IF(P9="Power BI",1,0.5))))*8+(10+(D9/100)*0.5)*8))*0.12*0.4+((((D9/100)*0.5+F9*0.5+G9*0.2+H9*0.8+I9*1+J9*3+K9*5+(D9/100)*0.3)*8+(L9*IF(O9="High",2,IF(O9="Medium",1,0.5)))*8+(M9*IF(P9="EC2 (Lift & Shift)",0.2,IF(P9="AWS QuickSight",1.5,IF(P9="Power BI",1,0.5))))*8+(10+(D9/100)*0.5)*8))*0.08*0.4 -> 1144.0042 | AO9: =AI9+AL9+((M9*IF(P9="EC2 (Lift & Shift)",0.2,IF(P9="AWS QuickSight",1.5,IF(P9="Power BI",1,0.5))))*8)*0.2+((10+(D9/100)*0.5)*8)*0.2+AE9+((((D9/100)*0.5+F9*0.5+G9*0.2+H9*0.8+I9*1+J9*3+K9*5+(D9/100)*0.3)*8+(L9*IF(O9="High",2,IF(O9="Medium",1,0.5)))*8+(M9*IF(P9="EC2 (Lift & Shift)",0.2,IF(P9="AWS QuickSight",1.5,IF(P9="Power BI",1,0.5))))*8+(10+(D9/100)*0.5)*8))*0.28*0.2+((((D9/100)*0.5+F9*0.5+G9*0.2+H9*0.8+I9*1+J9*3+K9*5+(D9/100)*0.3)*8+(L9*IF(O9="High",2,IF(O9="Medium",1,0.5)))*8+(M9*IF(P9="EC2 (Lift & Shift)",0.2,IF(P9="AWS QuickSight",1.5,IF(P9="Power BI",1,0.5))))*8+(10+(D9/100)*0.5)*8))*0.12*0.2+((((D9/100)*0.5+F9*0.5+G9*0.2+H9*0.8+I9*1+J9*3+K9*5+(D9/100)*0.3)*8+(L9*IF(O9="High",2,IF(O9="Medium",1,0.5)))*8+(M9*IF(P9="EC2 (Lift & Shift)",0.2,IF(P9="AWS QuickSight",1.5,IF(P9="Power BI",1,0.5))))*8+(10+(D9/100)*0.5)*8))*0.08*0.2 -> 563.70208 | AP9: ='✏️ SME Input'!S9 -> 15 | AQ9: ='✏️ SME Input'!T9 -> 2 | AR9: ='✏️ SME Input'!U9 -> Transactional
B10: ='✏️ SME Input'!B10 -> Customer Portal DB | C10: =IF(D10>1000,"T3 Complex",IF(D10>500,"T2 Moderate","T1 Simple")) -> T1 Simple | D10: ='✏️ SME Input'!D10 -> 180 | E10: ='✏️ SME Input'!E10 -> 80 | F10: ='✏️ SME Input'!F10 -> 45 | G10: ='✏️ SME Input'!G10 -> 30 | H10: ='✏️ SME Input'!H10 -> 5 | I10: ='✏️ SME Input'!I10 -> 3 | J10: ='✏️ SME Input'!J10 -> 0 | K10: ='✏️ SME Input'!K10 -> 0 | ... P10: ='✏️ SME Input'!P10 -> AWS QuickSight | Q10: ='✏️ SME Input'!C10 -> Wave 1 | R10: =((((D10/100)*0.5+F10*0.5+G10*0.2+H10*0.8+I10*1+J10*3+K10*5+(D10/100)*0.3)*8+(L10*IF(O10="High",2,IF(O10="Medium",1,0.5)))*8+(M10*IF(P10="EC2 (Lift & Shift)",0.2,IF(P10="AWS QuickSight",1.5,IF(P10="Power BI",1,0.5))))*8+(10+(D10/100)*0.5)*8))*0.08+(((D10/100)*0.5+F10*0.5+G10*0.2+H10*0.8+I10*1+J10*3+K10*5+(D10/100)*0.3)*8+(D10/100)*0.3*8)+((L10*IF(O10="High",2,IF(O10="Medium",1,0.5)))*8)+((M10*IF(P10="EC2 (Lift & Shift)",0.2,IF(P10="AWS QuickSight",1.5,IF(P10="Power BI",1,0.5))))*8)+((10+(D10/100)*0.5)*8)+((((D10/100)*0.5+F10*0.5+G10*0.2+H10*0.8+I10*1+J10*3+K10*5+(D10/100)*0.3)*8+(L10*IF(O10="High",2,IF(O10="Medium",1,0.5)))*8+(M10*IF(P10="EC2 (Lift & Shift)",0.2,IF(P10="AWS QuickSight",1.5,IF(P10="Power BI",1,0.5))))*8+(10+(D10/100)*0.5)*8))*0.28+((((D10/100)*0.5+F10*0.5+G10*0.2+H10*0.8+I10*1+J10*3+K10*5+(D10/100)*0.3)*8+(L10*IF(O10="High",2,IF(O10="Medium",1,0.5)))*8+(M10*IF(P10="EC2 (Lift & Shift)",0.2,IF(P10="AWS QuickSight",1.5,IF(P10="Power BI",1,0.5))))*8+(10+(D10/100)*0.5)*8))*0.12 -> 843.0656 | S10: =((((D10/100)*0.5+F10*0.5+G10*0.2+H10*0.8+I10*1+J10*3+K10*5+(D10/100)*0.3)*8+(L10*IF(O10="High",2,IF(O10="Medium",1,0.5)))*8+(M10*IF(P10="EC2 (Lift & Shift)",0.2,IF(P10="AWS QuickSight",1.5,IF(P10="Power BI",1,0.5))))*8+(10+(D10/100)*0.5)*8)*0.08)*(1-'📊 Dashboard'!C10/100)+((((D10/100)*0.5+F10*0.5+G10*0.2+H10*0.8+I10*1+J10*3+K10*5+(D10/100)*0.3)*8+(D10/100)*0.3*8))*(1-'📊 Dashboard'!C10/100)+((L10*IF(O10="High",2,IF(O10="Medium",1,0.5)))*8)*(1-'📊 Dashboard'!C11/100)+((M10*IF(P10="EC2 (Lift & Shift)",0.2,IF(P10="AWS QuickSight",1.5,IF(P10="Power BI",1,0.5))))*8)*(1-'📊 Dashboard'!C12/100)+((10+(D10/100)*0.5)*8)*(1-'📊 Dashboard'!C10/100)+((((D10/100)*0.5+F10*0.5+G10*0.2+H10*0.8+I10*1+J10*3+K10*5+(D10/100)*0.3)*8+(L10*IF(O10="High",2,IF(O10="Medium",1,0.5)))*8+(M10*IF(P10="EC2 (Lift & Shift)",0.2,IF(P10="AWS QuickSight",1.5,IF(P10="Power BI",1,0.5))))*8+(10+(D10/100)*0.5)*8)*0.28)*(1-'📊 Dashboard'!C13/100)+((((D10/100)*0.5+F10*0.5+G10*0.2+H10*0.8+I10*1+J10*3+K10*5+(D10/100)*0.3)*8+(L10*IF(O10="High",2,IF(O10="Medium",1,0.5)))*8+(M10*IF(P10="EC2 (Lift & Shift)",0.2,IF(P10="AWS QuickSight",1.5,IF(P10="Power BI",1,0.5))))*8+(10+(D10/100)*0.5)*8)*0.12)*(1-'📊 Dashboard'!C10/100) -> 621.21408 | T10: =S10*(1+'📊 Dashboard'!C14/100) -> 714.39619 | U10: =(((D10/100)*0.5+F10*0.5+G10*0.2+H10*0.8+I10*1+J10*3+K10*5+(D10/100)*0.3)*8+(L10*IF(O10="High",2,IF(O10="Medium",1,0.5)))*8+(M10*IF(P10="EC2 (Lift & Shift)",0.2,IF(P10="AWS QuickSight",1.5,IF(P10="Power BI",1,0.5))))*8+(10+(D10/100)*0.5)*8)*0.08 -> 45.3376 | V10: =((D10/100)*0.5+F10*0.5+G10*0.2+H10*0.8+I10*1+J10*3+K10*5+(D10/100)*0.3)*8+(D10/100)*0.3*8 -> 299.84 | W10: =(L10*IF(O10="High",2,IF(O10="Medium",1,0.5)))*8 -> 64 | X10: =(M10*IF(P10="EC2 (Lift & Shift)",0.2,IF(P10="AWS QuickSight",1.5,IF(P10="Power BI",1,0.5))))*8 -> 120 | Y10: =(10+(D10/100)*0.5)*8 -> 87.2 | Z10: =(((D10/100)*0.5+F10*0.5+G10*0.2+H10*0.8+I10*1+J10*3+K10*5+(D10/100)*0.3)*8+(L10*IF(O10="High",2,IF(O10="Medium",1,0.5)))*8+(M10*IF(P10="EC2 (Lift & Shift)",0.2,IF(P10="AWS QuickSight",1.5,IF(P10="Power BI",1,0.5))))*8+(10+(D10/100)*0.5)*8)*0.28 -> 158.6816 | AA10: =(((D10/100)*0.5+F10*0.5+G10*0.2+H10*0.8+I10*1+J10*3+K10*5+(D10/100)*0.3)*8+(L10*IF(O10="High",2,IF(O10="Medium",1,0.5)))*8+(M10*IF(P10="EC2 (Lift & Shift)",0.2,IF(P10="AWS QuickSight",1.5,IF(P10="Power BI",1,0.5))))*8+(10+(D10/100)*0.5)*8)*0.12 -> 68.0064 | AB10: ='✏️ SME Input'!R10 -> 0 | AC10: =AB10*0.75 -> 0 | AD10: =AB10*0.75 -> 0 | AE10: =AB10*0.75 -> 0 | AF10: =AB10*2.25 -> 0 | AG10: =(((D10/100)*0.5+F10*0.5+G10*0.2+H10*0.8+I10*1+J10*3+K10*5+(D10/100)*0.3)*8)*0.4 -> 118.208 | AH10: =(((D10/100)*0.5+F10*0.5+G10*0.2+H10*0.8+I10*1+J10*3+K10*5+(D10/100)*0.3)*8)*0.4 -> 118.208 | AI10: =(((D10/100)*0.5+F10*0.5+G10*0.2+H10*0.8+I10*1+J10*3+K10*5+(D10/100)*0.3)*8)*0.2 -> 59.104 | AJ10: =((L10*IF(O10="High",2,IF(O10="Medium",1,0.5)))*8)*0.5 -> 32 | AK10: =((L10*IF(O10="High",2,IF(O10="Medium",1,0.5)))*8)*0.35 -> 22.4 | AL10: =((L10*IF(O10="High",2,IF(O10="Medium",1,0.5)))*8)*0.15 -> 9.6 | AM10: =AG10+AJ10+((M10*IF(P10="EC2 (Lift & Shift)",0.2,IF(P10="AWS QuickSight",1.5,IF(P10="Power BI",1,0.5))))*8)*0.4+((10+(D10/100)*0.5)*8)*0.4+AC10+((((D10/100)*0.5+F10*0.5+G10*0.2+H10*0.8+I10*1+J10*3+K10*5+(D10/100)*0.3)*8+(L10*IF(O10="High",2,IF(O10="Medium",1,0.5)))*8+(M10*IF(P10="EC2 (Lift & Shift)",0.2,IF(P10="AWS QuickSight",1.5,IF(P10="Power BI",1,0.5))))*8+(10+(D10/100)*0.5)*8))*0.28*0.4+((((D10/100)*0.5+F10*0.5+G10*0.2+H10*0.8+I10*1+J10*3+K10*5+(D10/100)*0.3)*8+(L10*IF(O10="High",2,IF(O10="Medium",1,0.5)))*8+(M10*IF(P10="EC2 (Lift & Shift)",0.2,IF(P10="AWS QuickSight",1.5,IF(P10="Power BI",1,0.5))))*8+(10+(D10/100)*0.5)*8))*0.12*0.4+((((D10/100)*0.5+F10*0.5+G10*0.2+H10*0.8+I10*1+J10*3+K10*5+(D10/100)*0.3)*8+(L10*IF(O10="High",2,IF(O10="Medium",1,0.5)))*8+(M10*IF(P10="EC2 (Lift & Shift)",0.2,IF(P10="AWS QuickSight",1.5,IF(P10="Power BI",1,0.5))))*8+(10+(D10/100)*0.5)*8))*0.08*0.4 -> 341.89824 | AN10: =AH10+AK10+((M10*IF(P10="EC2 (Lift & Shift)",0.2,IF(P10="AWS QuickSight",1.5,IF(P10="Power BI",1,0.5))))*8)*0.4+((10+(D10/100)*0.5)*8)*0.4+AD10+((((D10/100)*0.5+F10*0.5+G10*0.2+H10*0.8+I10*1+J10*3+K10*5+(D10/100)*0.3)*8+(L10*IF(O10="High",2,IF(O10="Medium",1,0.5)))*8+(M10*IF(P10="EC2 (Lift & Shift)",0.2,IF(P10="AWS QuickSight",1.5,IF(P10="Power BI",1,0.5))))*8+(10+(D10/100)*0.5)*8))*0.28*0.4+((((D10/100)*0.5+F10*0.5+G10*0.2+H10*0.8+I10*1+J10*3+K10*5+(D10/100)*0.3)*8+(L10*IF(O10="High",2,IF(O10="Medium",1,0.5)))*8+(M10*IF(P10="EC2 (Lift & Shift)",0.2,IF(P10="AWS QuickSight",1.5,IF(P10="Power BI",1,0.5))))*8+(10+(D10/100)*0.5)*8))*0.12*0.4+((((D10/100)*0.5+F10*0.5+G10*0.2+H10*0.8+I10*1+J10*3+K10*5+(D10/100)*0.3)*8+(L10*IF(O10="High",2,IF(O10="Medium",1,0.5)))*8+(M10*IF(P10="EC2 (Lift & Shift)",0.2,IF(P10="AWS QuickSight",1.5,IF(P10="Power BI",1,0.5))))*8+(10+(D10/100)*0.5)*8))*0.08*0.4 -> 332.29824 | AO10: =AI10+AL10+((M10*IF(P10="EC2 (Lift & Shift)",0.2,IF(P10="AWS QuickSight",1.5,IF(P10="Power BI",1,0.5))))*8)*0.2+((10+(D10/100)*0.5)*8)*0.2+AE10+((((D10/100)*0.5+F10*0.5+G10*0.2+H10*0.8+I10*1+J10*3+K10*5+(D10/100)*0.3)*8+(L10*IF(O10="High",2,IF(O10="Medium",1,0.5)))*8+(M10*IF(P10="EC2 (Lift & Shift)",0.2,IF(P10="AWS QuickSight",1.5,IF(P10="Power BI",1,0.5))))*8+(10+(D10/100)*0.5)*8))*0.28*0.2+((((D10/100)*0.5+F10*0.5+G10*0.2+H10*0.8+I10*1+J10*3+K10*5+(D10/100)*0.3)*8+(L10*IF(O10="High",2,IF(O10="Medium",1,0.5)))*8+(M10*IF(P10="EC2 (Lift & Shift)",0.2,IF(P10="AWS QuickSight",1.5,IF(P10="Power BI",1,0.5))))*8+(10+(D10/100)*0.5)*8))*0.12*0.2+((((D10/100)*0.5+F10*0.5+G10*0.2+H10*0.8+I10*1+J10*3+K10*5+(D10/100)*0.3)*8+(L10*IF(O10="High",2,IF(O10="Medium",1,0.5)))*8+(M10*IF(P10="EC2 (Lift & Shift)",0.2,IF(P10="AWS QuickSight",1.5,IF(P10="Power BI",1,0.5))))*8+(10+(D10/100)*0.5)*8))*0.08*0.2 -> 164.54912 | AP10: ='✏️ SME Input'!S10 -> 0 | AQ10: ='✏️ SME Input'!T10 -> 0 | AR10: ='✏️ SME Input'!U10 -> None
B11: ='✏️ SME Input'!B11 -> Provisioning System | C11: =IF(D11>1000,"T3 Complex",IF(D11>500,"T2 Moderate","T1 Simple")) -> T2 Moderate | D11: ='✏️ SME Input'!D11 -> 650 | E11: ='✏️ SME Input'!E11 -> 150 | F11: ='✏️ SME Input'!F11 -> 110 | G11: ='✏️ SME Input'!G11 -> 55 | H11: ='✏️ SME Input'!H11 -> 14 | I11: ='✏️ SME Input'!I11 -> 10 | J11: ='✏️ SME Input'!J11 -> 3 | K11: ='✏️ SME Input'!K11 -> 2 | ... P11: ='✏️ SME Input'!P11 -> EC2 (Lift & Shift) | Q11: ='✏️ SME Input'!C11 -> Wave 2 | R11: =((((D11/100)*0.5+F11*0.5+G11*0.2+H11*0.8+I11*1+J11*3+K11*5+(D11/100)*0.3)*8+(L11*IF(O11="High",2,IF(O11="Medium",1,0.5)))*8+(M11*IF(P11="EC2 (Lift & Shift)",0.2,IF(P11="AWS QuickSight",1.5,IF(P11="Power BI",1,0.5))))*8+(10+(D11/100)*0.5)*8))*0.08+(((D11/100)*0.5+F11*0.5+G11*0.2+H11*0.8+I11*1+J11*3+K11*5+(D11/100)*0.3)*8+(D11/100)*0.3*8)+((L11*IF(O11="High",2,IF(O11="Medium",1,0.5)))*8)+((M11*IF(P11="EC2 (Lift & Shift)",0.2,IF(P11="AWS QuickSight",1.5,IF(P11="Power BI",1,0.5))))*8)+((10+(D11/100)*0.5)*8)+((((D11/100)*0.5+F11*0.5+G11*0.2+H11*0.8+I11*1+J11*3+K11*5+(D11/100)*0.3)*8+(L11*IF(O11="High",2,IF(O11="Medium",1,0.5)))*8+(M11*IF(P11="EC2 (Lift & Shift)",0.2,IF(P11="AWS QuickSight",1.5,IF(P11="Power BI",1,0.5))))*8+(10+(D11/100)*0.5)*8))*0.28+((((D11/100)*0.5+F11*0.5+G11*0.2+H11*0.8+I11*1+J11*3+K11*5+(D11/100)*0.3)*8+(L11*IF(O11="High",2,IF(O11="Medium",1,0.5)))*8+(M11*IF(P11="EC2 (Lift & Shift)",0.2,IF(P11="AWS QuickSight",1.5,IF(P11="Power BI",1,0.5))))*8+(10+(D11/100)*0.5)*8))*0.12 -> 2102.4 | S11: =((((D11/100)*0.5+F11*0.5+G11*0.2+H11*0.8+I11*1+J11*3+K11*5+(D11/100)*0.3)*8+(L11*IF(O11="High",2,IF(O11="Medium",1,0.5)))*8+(M11*IF(P11="EC2 (Lift & Shift)",0.2,IF(P11="AWS QuickSight",1.5,IF(P11="Power BI",1,0.5))))*8+(10+(D11/100)*0.5)*8)*0.08)*(1-'📊 Dashboard'!C10/100)+((((D11/100)*0.5+F11*0.5+G11*0.2+H11*0.8+I11*1+J11*3+K11*5+(D11/100)*0.3)*8+(D11/100)*0.3*8))*(1-'📊 Dashboard'!C10/100)+((L11*IF(O11="High",2,IF(O11="Medium",1,0.5)))*8)*(1-'📊 Dashboard'!C11/100)+((M11*IF(P11="EC2 (Lift & Shift)",0.2,IF(P11="AWS QuickSight",1.5,IF(P11="Power BI",1,0.5))))*8)*(1-'📊 Dashboard'!C12/100)+((10+(D11/100)*0.5)*8)*(1-'📊 Dashboard'!C10/100)+((((D11/100)*0.5+F11*0.5+G11*0.2+H11*0.8+I11*1+J11*3+K11*5+(D11/100)*0.3)*8+(L11*IF(O11="High",2,IF(O11="Medium",1,0.5)))*8+(M11*IF(P11="EC2 (Lift & Shift)",0.2,IF(P11="AWS QuickSight",1.5,IF(P11="Power BI",1,0.5))))*8+(10+(D11/100)*0.5)*8)*0.28)*(1-'📊 Dashboard'!C13/100)+((((D11/100)*0.5+F11*0.5+G11*0.2+H11*0.8+I11*1+J11*3+K11*5+(D11/100)*0.3)*8+(L11*IF(O11="High",2,IF(O11="Medium",1,0.5)))*8+(M11*IF(P11="EC2 (Lift & Shift)",0.2,IF(P11="AWS QuickSight",1.5,IF(P11="Power BI",1,0.5))))*8+(10+(D11/100)*0.5)*8)*0.12)*(1-'📊 Dashboard'!C10/100) -> 1533.24 | T11: =S11*(1+'📊 Dashboard'!C14/100) -> 1763.226 | U11: =(((D11/100)*0.5+F11*0.5+G11*0.2+H11*0.8+I11*1+J11*3+K11*5+(D11/100)*0.3)*8+(L11*IF(O11="High",2,IF(O11="Medium",1,0.5)))*8+(M11*IF(P11="EC2 (Lift & Shift)",0.2,IF(P11="AWS QuickSight",1.5,IF(P11="Power BI",1,0.5))))*8+(10+(D11/100)*0.5)*8)*0.08 -> 112.8 | V11: =((D11/100)*0.5+F11*0.5+G11*0.2+H11*0.8+I11*1+J11*3+K11*5+(D11/100)*0.3)*8+(D11/100)*0.3*8 -> 906.8 | W11: =(L11*IF(O11="High",2,IF(O11="Medium",1,0.5)))*8 -> 384 | X11: =(M11*IF(P11="EC2 (Lift & Shift)",0.2,IF(P11="AWS QuickSight",1.5,IF(P11="Power BI",1,0.5))))*8 -> 28.8 | Y11: =(10+(D11/100)*0.5)*8 -> 106 | Z11: =(((D11/100)*0.5+F11*0.5+G11*0.2+H11*0.8+I11*1+J11*3+K11*5+(D11/100)*0.3)*8+(L11*IF(O11="High",2,IF(O11="Medium",1,0.5)))*8+(M11*IF(P11="EC2 (Lift & Shift)",0.2,IF(P11="AWS QuickSight",1.5,IF(P11="Power BI",1,0.5))))*8+(10+(D11/100)*0.5)*8)*0.28 -> 394.8 | AA11: =(((D11/100)*0.5+F11*0.5+G11*0.2+H11*0.8+I11*1+J11*3+K11*5+(D11/100)*0.3)*8+(L11*IF(O11="High",2,IF(O11="Medium",1,0.5)))*8+(M11*IF(P11="EC2 (Lift & Shift)",0.2,IF(P11="AWS QuickSight",1.5,IF(P11="Power BI",1,0.5))))*8+(10+(D11/100)*0.5)*8)*0.12 -> 169.2 | AB11: ='✏️ SME Input'!R11 -> 8 | AC11: =AB11*0.75 -> 6 | AD11: =AB11*0.75 -> 6 | AE11: =AB11*0.75 -> 6 | AF11: =AB11*2.25 -> 18 | AG11: =(((D11/100)*0.5+F11*0.5+G11*0.2+H11*0.8+I11*1+J11*3+K11*5+(D11/100)*0.3)*8)*0.4 -> 356.48 | AH11: =(((D11/100)*0.5+F11*0.5+G11*0.2+H11*0.8+I11*1+J11*3+K11*5+(D11/100)*0.3)*8)*0.4 -> 356.48 | AI11: =(((D11/100)*0.5+F11*0.5+G11*0.2+H11*0.8+I11*1+J11*3+K11*5+(D11/100)*0.3)*8)*0.2 -> 178.24 | AJ11: =((L11*IF(O11="High",2,IF(O11="Medium",1,0.5)))*8)*0.5 -> 192 | AK11: =((L11*IF(O11="High",2,IF(O11="Medium",1,0.5)))*8)*0.35 -> 134.4 | AL11: =((L11*IF(O11="High",2,IF(O11="Medium",1,0.5)))*8)*0.15 -> 57.6 | AM11: =AG11+AJ11+((M11*IF(P11="EC2 (Lift & Shift)",0.2,IF(P11="AWS QuickSight",1.5,IF(P11="Power BI",1,0.5))))*8)*0.4+((10+(D11/100)*0.5)*8)*0.4+AC11+((((D11/100)*0.5+F11*0.5+G11*0.2+H11*0.8+I11*1+J11*3+K11*5+(D11/100)*0.3)*8+(L11*IF(O11="High",2,IF(O11="Medium",1,0.5)))*8+(M11*IF(P11="EC2 (Lift & Shift)",0.2,IF(P11="AWS QuickSight",1.5,IF(P11="Power BI",1,0.5))))*8+(10+(D11/100)*0.5)*8))*0.28*0.4+((((D11/100)*0.5+F11*0.5+G11*0.2+H11*0.8+I11*1+J11*3+K11*5+(D11/100)*0.3)*8+(L11*IF(O11="High",2,IF(O11="Medium",1,0.5)))*8+(M11*IF(P11="EC2 (Lift & Shift)",0.2,IF(P11="AWS QuickSight",1.5,IF(P11="Power BI",1,0.5))))*8+(10+(D11/100)*0.5)*8))*0.12*0.4+((((D11/100)*0.5+F11*0.5+G11*0.2+H11*0.8+I11*1+J11*3+K11*5+(D11/100)*0.3)*8+(L11*IF(O11="High",2,IF(O11="Medium",1,0.5)))*8+(M11*IF(P11="EC2 (Lift & Shift)",0.2,IF(P11="AWS QuickSight",1.5,IF(P11="Power BI",1,0.5))))*8+(10+(D11/100)*0.5)*8))*0.08*0.4 -> 879.12 | AN11: =AH11+AK11+((M11*IF(P11="EC2 (Lift & Shift)",0.2,IF(P11="AWS QuickSight",1.5,IF(P11="Power BI",1,0.5))))*8)*0.4+((10+(D11/100)*0.5)*8)*0.4+AD11+((((D11/100)*0.5+F11*0.5+G11*0.2+H11*0.8+I11*1+J11*3+K11*5+(D11/100)*0.3)*8+(L11*IF(O11="High",2,IF(O11="Medium",1,0.5)))*8+(M11*IF(P11="EC2 (Lift & Shift)",0.2,IF(P11="AWS QuickSight",1.5,IF(P11="Power BI",1,0.5))))*8+(10+(D11/100)*0.5)*8))*0.28*0.4+((((D11/100)*0.5+F11*0.5+G11*0.2+H11*0.8+I11*1+J11*3+K11*5+(D11/100)*0.3)*8+(L11*IF(O11="High",2,IF(O11="Medium",1,0.5)))*8+(M11*IF(P11="EC2 (Lift & Shift)",0.2,IF(P11="AWS QuickSight",1.5,IF(P11="Power BI",1,0.5))))*8+(10+(D11/100)*0.5)*8))*0.12*0.4+((((D11/100)*0.5+F11*0.5+G11*0.2+H11*0.8+I11*1+J11*3+K11*5+(D11/100)*0.3)*8+(L11*IF(O11="High",2,IF(O11="Medium",1,0.5)))*8+(M11*IF(P11="EC2 (Lift & Shift)",0.2,IF(P11="AWS QuickSight",1.5,IF(P11="Power BI",1,0.5))))*8+(10+(D11/100)*0.5)*8))*0.08*0.4 -> 821.52 | AO11: =AI11+AL11+((M11*IF(P11="EC2 (Lift & Shift)",0.2,IF(P11="AWS QuickSight",1.5,IF(P11="Power BI",1,0.5))))*8)*0.2+((10+(D11/100)*0.5)*8)*0.2+AE11+((((D11/100)*0.5+F11*0.5+G11*0.2+H11*0.8+I11*1+J11*3+K11*5+(D11/100)*0.3)*8+(L11*IF(O11="High",2,IF(O11="Medium",1,0.5)))*8+(M11*IF(P11="EC2 (Lift & Shift)",0.2,IF(P11="AWS QuickSight",1.5,IF(P11="Power BI",1,0.5))))*8+(10+(D11/100)*0.5)*8))*0.28*0.2+((((D11/100)*0.5+F11*0.5+G11*0.2+H11*0.8+I11*1+J11*3+K11*5+(D11/100)*0.3)*8+(L11*IF(O11="High",2,IF(O11="Medium",1,0.5)))*8+(M11*IF(P11="EC2 (Lift & Shift)",0.2,IF(P11="AWS QuickSight",1.5,IF(P11="Power BI",1,0.5))))*8+(10+(D11/100)*0.5)*8))*0.12*0.2+((((D11/100)*0.5+F11*0.5+G11*0.2+H11*0.8+I11*1+J11*3+K11*5+(D11/100)*0.3)*8+(L11*IF(O11="High",2,IF(O11="Medium",1,0.5)))*8+(M11*IF(P11="EC2 (Lift & Shift)",0.2,IF(P11="AWS QuickSight",1.5,IF(P11="Power BI",1,0.5))))*8+(10+(D11/100)*0.5)*8))*0.08*0.2 -> 404.16 | AP11: ='✏️ SME Input'!S11 -> 6 | AQ11: ='✏️ SME Input'!T11 -> 0 | AR11: ='✏️ SME Input'!U11 -> Transactional
B12: ='✏️ SME Input'!B12 -> Revenue Assurance | C12: =IF(D12>1000,"T3 Complex",IF(D12>500,"T2 Moderate","T1 Simple")) -> T3 Complex | D12: ='✏️ SME Input'!D12 -> 1200 | E12: ='✏️ SME Input'!E12 -> 280 | F12: ='✏️ SME Input'!F12 -> 190 | G12: ='✏️ SME Input'!G12 -> 90 | H12: ='✏️ SME Input'!H12 -> 22 | I12: ='✏️ SME Input'!I12 -> 20 | J12: ='✏️ SME Input'!J12 -> 6 | K12: ='✏️ SME Input'!K12 -> 8 | ... P12: ='✏️ SME Input'!P12 -> EC2 (Lift & Shift) | Q12: ='✏️ SME Input'!C12 -> Wave 4 | R12: =((((D12/100)*0.5+F12*0.5+G12*0.2+H12*0.8+I12*1+J12*3+K12*5+(D12/100)*0.3)*8+(L12*IF(O12="High",2,IF(O12="Medium",1,0.5)))*8+(M12*IF(P12="EC2 (Lift & Shift)",0.2,IF(P12="AWS QuickSight",1.5,IF(P12="Power BI",1,0.5))))*8+(10+(D12/100)*0.5)*8))*0.08+(((D12/100)*0.5+F12*0.5+G12*0.2+H12*0.8+I12*1+J12*3+K12*5+(D12/100)*0.3)*8+(D12/100)*0.3*8)+((L12*IF(O12="High",2,IF(O12="Medium",1,0.5)))*8)+((M12*IF(P12="EC2 (Lift & Shift)",0.2,IF(P12="AWS QuickSight",1.5,IF(P12="Power BI",1,0.5))))*8)+((10+(D12/100)*0.5)*8)+((((D12/100)*0.5+F12*0.5+G12*0.2+H12*0.8+I12*1+J12*3+K12*5+(D12/100)*0.3)*8+(L12*IF(O12="High",2,IF(O12="Medium",1,0.5)))*8+(M12*IF(P12="EC2 (Lift & Shift)",0.2,IF(P12="AWS QuickSight",1.5,IF(P12="Power BI",1,0.5))))*8+(10+(D12/100)*0.5)*8))*0.28+((((D12/100)*0.5+F12*0.5+G12*0.2+H12*0.8+I12*1+J12*3+K12*5+(D12/100)*0.3)*8+(L12*IF(O12="High",2,IF(O12="Medium",1,0.5)))*8+(M12*IF(P12="EC2 (Lift & Shift)",0.2,IF(P12="AWS QuickSight",1.5,IF(P12="Power BI",1,0.5))))*8+(10+(D12/100)*0.5)*8))*0.12 -> 3867.328 | S12: =((((D12/100)*0.5+F12*0.5+G12*0.2+H12*0.8+I12*1+J12*3+K12*5+(D12/100)*0.3)*8+(L12*IF(O12="High",2,IF(O12="Medium",1,0.5)))*8+(M12*IF(P12="EC2 (Lift & Shift)",0.2,IF(P12="AWS QuickSight",1.5,IF(P12="Power BI",1,0.5))))*8+(10+(D12/100)*0.5)*8)*0.08)*(1-'📊 Dashboard'!C10/100)+((((D12/100)*0.5+F12*0.5+G12*0.2+H12*0.8+I12*1+J12*3+K12*5+(D12/100)*0.3)*8+(D12/100)*0.3*8))*(1-'📊 Dashboard'!C10/100)+((L12*IF(O12="High",2,IF(O12="Medium",1,0.5)))*8)*(1-'📊 Dashboard'!C11/100)+((M12*IF(P12="EC2 (Lift & Shift)",0.2,IF(P12="AWS QuickSight",1.5,IF(P12="Power BI",1,0.5))))*8)*(1-'📊 Dashboard'!C12/100)+((10+(D12/100)*0.5)*8)*(1-'📊 Dashboard'!C10/100)+((((D12/100)*0.5+F12*0.5+G12*0.2+H12*0.8+I12*1+J12*3+K12*5+(D12/100)*0.3)*8+(L12*IF(O12="High",2,IF(O12="Medium",1,0.5)))*8+(M12*IF(P12="EC2 (Lift & Shift)",0.2,IF(P12="AWS QuickSight",1.5,IF(P12="Power BI",1,0.5))))*8+(10+(D12/100)*0.5)*8)*0.28)*(1-'📊 Dashboard'!C13/100)+((((D12/100)*0.5+F12*0.5+G12*0.2+H12*0.8+I12*1+J12*3+K12*5+(D12/100)*0.3)*8+(L12*IF(O12="High",2,IF(O12="Medium",1,0.5)))*8+(M12*IF(P12="EC2 (Lift & Shift)",0.2,IF(P12="AWS QuickSight",1.5,IF(P12="Power BI",1,0.5))))*8+(10+(D12/100)*0.5)*8)*0.12)*(1-'📊 Dashboard'!C10/100) -> 2819.7504 | T12: =S12*(1+'📊 Dashboard'!C14/100) -> 3242.713 | U12: =(((D12/100)*0.5+F12*0.5+G12*0.2+H12*0.8+I12*1+J12*3+K12*5+(D12/100)*0.3)*8+(L12*IF(O12="High",2,IF(O12="Medium",1,0.5)))*8+(M12*IF(P12="EC2 (Lift & Shift)",0.2,IF(P12="AWS QuickSight",1.5,IF(P12="Power BI",1,0.5))))*8+(10+(D12/100)*0.5)*8)*0.08 -> 207.488 | V12: =((D12/100)*0.5+F12*0.5+G12*0.2+H12*0.8+I12*1+J12*3+K12*5+(D12/100)*0.3)*8+(D12/100)*0.3*8 -> 1774.4 | W12: =(L12*IF(O12="High",2,IF(O12="Medium",1,0.5)))*8 -> 640 | X12: =(M12*IF(P12="EC2 (Lift & Shift)",0.2,IF(P12="AWS QuickSight",1.5,IF(P12="Power BI",1,0.5))))*8 -> 80 | Y12: =(10+(D12/100)*0.5)*8 -> 128 | Z12: =(((D12/100)*0.5+F12*0.5+G12*0.2+H12*0.8+I12*1+J12*3+K12*5+(D12/100)*0.3)*8+(L12*IF(O12="High",2,IF(O12="Medium",1,0.5)))*8+(M12*IF(P12="EC2 (Lift & Shift)",0.2,IF(P12="AWS QuickSight",1.5,IF(P12="Power BI",1,0.5))))*8+(10+(D12/100)*0.5)*8)*0.28 -> 726.208 | AA12: =(((D12/100)*0.5+F12*0.5+G12*0.2+H12*0.8+I12*1+J12*3+K12*5+(D12/100)*0.3)*8+(L12*IF(O12="High",2,IF(O12="Medium",1,0.5)))*8+(M12*IF(P12="EC2 (Lift & Shift)",0.2,IF(P12="AWS QuickSight",1.5,IF(P12="Power BI",1,0.5))))*8+(10+(D12/100)*0.5)*8)*0.12 -> 311.232 | AB12: ='✏️ SME Input'!R12 -> 20 | AC12: =AB12*0.75 -> 15 | AD12: =AB12*0.75 -> 15 | AE12: =AB12*0.75 -> 15 | AF12: =AB12*2.25 -> 45 | AG12: =(((D12/100)*0.5+F12*0.5+G12*0.2+H12*0.8+I12*1+J12*3+K12*5+(D12/100)*0.3)*8)*0.4 -> 698.24 | AH12: =(((D12/100)*0.5+F12*0.5+G12*0.2+H12*0.8+I12*1+J12*3+K12*5+(D12/100)*0.3)*8)*0.4 -> 698.24 | AI12: =(((D12/100)*0.5+F12*0.5+G12*0.2+H12*0.8+I12*1+J12*3+K12*5+(D12/100)*0.3)*8)*0.2 -> 349.12 | AJ12: =((L12*IF(O12="High",2,IF(O12="Medium",1,0.5)))*8)*0.5 -> 320 | AK12: =((L12*IF(O12="High",2,IF(O12="Medium",1,0.5)))*8)*0.35 -> 224 | AL12: =((L12*IF(O12="High",2,IF(O12="Medium",1,0.5)))*8)*0.15 -> 96 | AM12: =AG12+AJ12+((M12*IF(P12="EC2 (Lift & Shift)",0.2,IF(P12="AWS QuickSight",1.5,IF(P12="Power BI",1,0.5))))*8)*0.4+((10+(D12/100)*0.5)*8)*0.4+AC12+((((D12/100)*0.5+F12*0.5+G12*0.2+H12*0.8+I12*1+J12*3+K12*5+(D12/100)*0.3)*8+(L12*IF(O12="High",2,IF(O12="Medium",1,0.5)))*8+(M12*IF(P12="EC2 (Lift & Shift)",0.2,IF(P12="AWS QuickSight",1.5,IF(P12="Power BI",1,0.5))))*8+(10+(D12/100)*0.5)*8))*0.28*0.4+((((D12/100)*0.5+F12*0.5+G12*0.2+H12*0.8+I12*1+J12*3+K12*5+(D12/100)*0.3)*8+(L12*IF(O12="High",2,IF(O12="Medium",1,0.5)))*8+(M12*IF(P12="EC2 (Lift & Shift)",0.2,IF(P12="AWS QuickSight",1.5,IF(P12="Power BI",1,0.5))))*8+(10+(D12/100)*0.5)*8))*0.12*0.4+((((D12/100)*0.5+F12*0.5+G12*0.2+H12*0.8+I12*1+J12*3+K12*5+(D12/100)*0.3)*8+(L12*IF(O12="High",2,IF(O12="Medium",1,0.5)))*8+(M12*IF(P12="EC2 (Lift & Shift)",0.2,IF(P12="AWS QuickSight",1.5,IF(P12="Power BI",1,0.5))))*8+(10+(D12/100)*0.5)*8))*0.08*0.4 -> 1614.4112 | AN12: =AH12+AK12+((M12*IF(P12="EC2 (Lift & Shift)",0.2,IF(P12="AWS QuickSight",1.5,IF(P12="Power BI",1,0.5))))*8)*0.4+((10+(D12/100)*0.5)*8)*0.4+AD12+((((D12/100)*0.5+F12*0.5+G12*0.2+H12*0.8+I12*1+J12*3+K12*5+(D12/100)*0.3)*8+(L12*IF(O12="High",2,IF(O12="Medium",1,0.5)))*8+(M12*IF(P12="EC2 (Lift & Shift)",0.2,IF(P12="AWS QuickSight",1.5,IF(P12="Power BI",1,0.5))))*8+(10+(D12/100)*0.5)*8))*0.28*0.4+((((D12/100)*0.5+F12*0.5+G12*0.2+H12*0.8+I12*1+J12*3+K12*5+(D12/100)*0.3)*8+(L12*IF(O12="High",2,IF(O12="Medium",1,0.5)))*8+(M12*IF(P12="EC2 (Lift & Shift)",0.2,IF(P12="AWS QuickSight",1.5,IF(P12="Power BI",1,0.5))))*8+(10+(D12/100)*0.5)*8))*0.12*0.4+((((D12/100)*0.5+F12*0.5+G12*0.2+H12*0.8+I12*1+J12*3+K12*5+(D12/100)*0.3)*8+(L12*IF(O12="High",2,IF(O12="Medium",1,0.5)))*8+(M12*IF(P12="EC2 (Lift & Shift)",0.2,IF(P12="AWS QuickSight",1.5,IF(P12="Power BI",1,0.5))))*8+(10+(D12/100)*0.5)*8))*0.08*0.4 -> 1518.4112 | AO12: =AI12+AL12+((M12*IF(P12="EC2 (Lift & Shift)",0.2,IF(P12="AWS QuickSight",1.5,IF(P12="Power BI",1,0.5))))*8)*0.2+((10+(D12/100)*0.5)*8)*0.2+AE12+((((D12/100)*0.5+F12*0.5+G12*0.2+H12*0.8+I12*1+J12*3+K12*5+(D12/100)*0.3)*8+(L12*IF(O12="High",2,IF(O12="Medium",1,0.5)))*8+(M12*IF(P12="EC2 (Lift & Shift)",0.2,IF(P12="AWS QuickSight",1.5,IF(P12="Power BI",1,0.5))))*8+(10+(D12/100)*0.5)*8))*0.28*0.2+((((D12/100)*0.5+F12*0.5+G12*0.2+H12*0.8+I12*1+J12*3+K12*5+(D12/100)*0.3)*8+(L12*IF(O12="High",2,IF(O12="Medium",1,0.5)))*8+(M12*IF(P12="EC2 (Lift & Shift)",0.2,IF(P12="AWS QuickSight",1.5,IF(P12="Power BI",1,0.5))))*8+(10+(D12/100)*0.5)*8))*0.12*0.2+((((D12/100)*0.5+F12*0.5+G12*0.2+H12*0.8+I12*1+J12*3+K12*5+(D12/100)*0.3)*8+(L12*IF(O12="High",2,IF(O12="Medium",1,0.5)))*8+(M12*IF(P12="EC2 (Lift & Shift)",0.2,IF(P12="AWS QuickSight",1.5,IF(P12="Power BI",1,0.5))))*8+(10+(D12/100)*0.5)*8))*0.08*0.2 -> 750.7056 | AP12: ='✏️ SME Input'!S12 -> 20 | AQ12: ='✏️ SME Input'!T12 -> 3 | AR12: ='✏️ SME Input'!U12 -> Mixed
B13: ='✏️ SME Input'!B13 -> Fraud Management | C13: =IF(D13>1000,"T3 Complex",IF(D13>500,"T2 Moderate","T1 Simple")) -> T1 Simple | D13: ='✏️ SME Input'!D13 -> 340 | E13: ='✏️ SME Input'!E13 -> 95 | F13: ='✏️ SME Input'!F13 -> 65 | G13: ='✏️ SME Input'!G13 -> 35 | H13: ='✏️ SME Input'!H13 -> 8 | I13: ='✏️ SME Input'!I13 -> 6 | J13: ='✏️ SME Input'!J13 -> 1 | K13: ='✏️ SME Input'!K13 -> 4 | ... P13: ='✏️ SME Input'!P13 -> Power BI | Q13: ='✏️ SME Input'!C13 -> Wave 2 | R13: =((((D13/100)*0.5+F13*0.5+G13*0.2+H13*0.8+I13*1+J13*3+K13*5+(D13/100)*0.3)*8+(L13*IF(O13="High",2,IF(O13="Medium",1,0.5)))*8+(M13*IF(P13="EC2 (Lift & Shift)",0.2,IF(P13="AWS QuickSight",1.5,IF(P13="Power BI",1,0.5))))*8+(10+(D13/100)*0.5)*8))*0.08+(((D13/100)*0.5+F13*0.5+G13*0.2+H13*0.8+I13*1+J13*3+K13*5+(D13/100)*0.3)*8+(D13/100)*0.3*8)+((L13*IF(O13="High",2,IF(O13="Medium",1,0.5)))*8)+((M13*IF(P13="EC2 (Lift & Shift)",0.2,IF(P13="AWS QuickSight",1.5,IF(P13="Power BI",1,0.5))))*8)+((10+(D13/100)*0.5)*8)+((((D13/100)*0.5+F13*0.5+G13*0.2+H13*0.8+I13*1+J13*3+K13*5+(D13/100)*0.3)*8+(L13*IF(O13="High",2,IF(O13="Medium",1,0.5)))*8+(M13*IF(P13="EC2 (Lift & Shift)",0.2,IF(P13="AWS QuickSight",1.5,IF(P13="Power BI",1,0.5))))*8+(10+(D13/100)*0.5)*8))*0.28+((((D13/100)*0.5+F13*0.5+G13*0.2+H13*0.8+I13*1+J13*3+K13*5+(D13/100)*0.3)*8+(L13*IF(O13="High",2,IF(O13="Medium",1,0.5)))*8+(M13*IF(P13="EC2 (Lift & Shift)",0.2,IF(P13="AWS QuickSight",1.5,IF(P13="Power BI",1,0.5))))*8+(10+(D13/100)*0.5)*8))*0.12 -> 1385.3888 | S13: =((((D13/100)*0.5+F13*0.5+G13*0.2+H13*0.8+I13*1+J13*3+K13*5+(D13/100)*0.3)*8+(L13*IF(O13="High",2,IF(O13="Medium",1,0.5)))*8+(M13*IF(P13="EC2 (Lift & Shift)",0.2,IF(P13="AWS QuickSight",1.5,IF(P13="Power BI",1,0.5))))*8+(10+(D13/100)*0.5)*8)*0.08)*(1-'📊 Dashboard'!C10/100)+((((D13/100)*0.5+F13*0.5+G13*0.2+H13*0.8+I13*1+J13*3+K13*5+(D13/100)*0.3)*8+(D13/100)*0.3*8))*(1-'📊 Dashboard'!C10/100)+((L13*IF(O13="High",2,IF(O13="Medium",1,0.5)))*8)*(1-'📊 Dashboard'!C11/100)+((M13*IF(P13="EC2 (Lift & Shift)",0.2,IF(P13="AWS QuickSight",1.5,IF(P13="Power BI",1,0.5))))*8)*(1-'📊 Dashboard'!C12/100)+((10+(D13/100)*0.5)*8)*(1-'📊 Dashboard'!C10/100)+((((D13/100)*0.5+F13*0.5+G13*0.2+H13*0.8+I13*1+J13*3+K13*5+(D13/100)*0.3)*8+(L13*IF(O13="High",2,IF(O13="Medium",1,0.5)))*8+(M13*IF(P13="EC2 (Lift & Shift)",0.2,IF(P13="AWS QuickSight",1.5,IF(P13="Power BI",1,0.5))))*8+(10+(D13/100)*0.5)*8)*0.28)*(1-'📊 Dashboard'!C13/100)+((((D13/100)*0.5+F13*0.5+G13*0.2+H13*0.8+I13*1+J13*3+K13*5+(D13/100)*0.3)*8+(L13*IF(O13="High",2,IF(O13="Medium",1,0.5)))*8+(M13*IF(P13="EC2 (Lift & Shift)",0.2,IF(P13="AWS QuickSight",1.5,IF(P13="Power BI",1,0.5))))*8+(10+(D13/100)*0.5)*8)*0.12)*(1-'📊 Dashboard'!C10/100) -> 1011.4278 | T13: =S13*(1+'📊 Dashboard'!C14/100) -> 1163.142 | U13: =(((D13/100)*0.5+F13*0.5+G13*0.2+H13*0.8+I13*1+J13*3+K13*5+(D13/100)*0.3)*8+(L13*IF(O13="High",2,IF(O13="Medium",1,0.5)))*8+(M13*IF(P13="EC2 (Lift & Shift)",0.2,IF(P13="AWS QuickSight",1.5,IF(P13="Power BI",1,0.5))))*8+(10+(D13/100)*0.5)*8)*0.08 -> 74.4448 | V13: =((D13/100)*0.5+F13*0.5+G13*0.2+H13*0.8+I13*1+J13*3+K13*5+(D13/100)*0.3)*8+(D13/100)*0.3*8 -> 629.12 | W13: =(L13*IF(O13="High",2,IF(O13="Medium",1,0.5)))*8 -> 120 | X13: =(M13*IF(P13="EC2 (Lift & Shift)",0.2,IF(P13="AWS QuickSight",1.5,IF(P13="Power BI",1,0.5))))*8 -> 96 | Y13: =(10+(D13/100)*0.5)*8 -> 93.6 | Z13: =(((D13/100)*0.5+F13*0.5+G13*0.2+H13*0.8+I13*1+J13*3+K13*5+(D13/100)*0.3)*8+(L13*IF(O13="High",2,IF(O13="Medium",1,0.5)))*8+(M13*IF(P13="EC2 (Lift & Shift)",0.2,IF(P13="AWS QuickSight",1.5,IF(P13="Power BI",1,0.5))))*8+(10+(D13/100)*0.5)*8)*0.28 -> 260.5568 | AA13: =(((D13/100)*0.5+F13*0.5+G13*0.2+H13*0.8+I13*1+J13*3+K13*5+(D13/100)*0.3)*8+(L13*IF(O13="High",2,IF(O13="Medium",1,0.5)))*8+(M13*IF(P13="EC2 (Lift & Shift)",0.2,IF(P13="AWS QuickSight",1.5,IF(P13="Power BI",1,0.5))))*8+(10+(D13/100)*0.5)*8)*0.12 -> 111.6672 | AB13: ='✏️ SME Input'!R13 -> 3 | AC13: =AB13*0.75 -> 2.25 | AD13: =AB13*0.75 -> 2.25 | AE13: =AB13*0.75 -> 2.25 | AF13: =AB13*2.25 -> 6.75 | AG13: =(((D13/100)*0.5+F13*0.5+G13*0.2+H13*0.8+I13*1+J13*3+K13*5+(D13/100)*0.3)*8)*0.4 -> 248.384 | AH13: =(((D13/100)*0.5+F13*0.5+G13*0.2+H13*0.8+I13*1+J13*3+K13*5+(D13/100)*0.3)*8)*0.4 -> 248.384 | AI13: =(((D13/100)*0.5+F13*0.5+G13*0.2+H13*0.8+I13*1+J13*3+K13*5+(D13/100)*0.3)*8)*0.2 -> 124.192 | AJ13: =((L13*IF(O13="High",2,IF(O13="Medium",1,0.5)))*8)*0.5 -> 60 | AK13: =((L13*IF(O13="High",2,IF(O13="Medium",1,0.5)))*8)*0.35 -> 42 | AL13: =((L13*IF(O13="High",2,IF(O13="Medium",1,0.5)))*8)*0.15 -> 18 | AM13: =AG13+AJ13+((M13*IF(P13="EC2 (Lift & Shift)",0.2,IF(P13="AWS QuickSight",1.5,IF(P13="Power BI",1,0.5))))*8)*0.4+((10+(D13/100)*0.5)*8)*0.4+AC13+((((D13/100)*0.5+F13*0.5+G13*0.2+H13*0.8+I13*1+J13*3+K13*5+(D13/100)*0.3)*8+(L13*IF(O13="High",2,IF(O13="Medium",1,0.5)))*8+(M13*IF(P13="EC2 (Lift & Shift)",0.2,IF(P13="AWS QuickSight",1.5,IF(P13="Power BI",1,0.5))))*8+(10+(D13/100)*0.5)*8))*0.28*0.4+((((D13/100)*0.5+F13*0.5+G13*0.2+H13*0.8+I13*1+J13*3+K13*5+(D13/100)*0.3)*8+(L13*IF(O13="High",2,IF(O13="Medium",1,0.5)))*8+(M13*IF(P13="EC2 (Lift & Shift)",0.2,IF(P13="AWS QuickSight",1.5,IF(P13="Power BI",1,0.5))))*8+(10+(D13/100)*0.5)*8))*0.12*0.4+((((D13/100)*0.5+F13*0.5+G13*0.2+H13*0.8+I13*1+J13*3+K13*5+(D13/100)*0.3)*8+(L13*IF(O13="High",2,IF(O13="Medium",1,0.5)))*8+(M13*IF(P13="EC2 (Lift & Shift)",0.2,IF(P13="AWS QuickSight",1.5,IF(P13="Power BI",1,0.5))))*8+(10+(D13/100)*0.5)*8))*0.08*0.4 -> 565.14152 | AN13: =AH13+AK13+((M13*IF(P13="EC2 (Lift & Shift)",0.2,IF(P13="AWS QuickSight",1.5,IF(P13="Power BI",1,0.5))))*8)*0.4+((10+(D13/100)*0.5)*8)*0.4+AD13+((((D13/100)*0.5+F13*0.5+G13*0.2+H13*0.8+I13*1+J13*3+K13*5+(D13/100)*0.3)*8+(L13*IF(O13="High",2,IF(O13="Medium",1,0.5)))*8+(M13*IF(P13="EC2 (Lift & Shift)",0.2,IF(P13="AWS QuickSight",1.5,IF(P13="Power BI",1,0.5))))*8+(10+(D13/100)*0.5)*8))*0.28*0.4+((((D13/100)*0.5+F13*0.5+G13*0.2+H13*0.8+I13*1+J13*3+K13*5+(D13/100)*0.3)*8+(L13*IF(O13="High",2,IF(O13="Medium",1,0.5)))*8+(M13*IF(P13="EC2 (Lift & Shift)",0.2,IF(P13="AWS QuickSight",1.5,IF(P13="Power BI",1,0.5))))*8+(10+(D13/100)*0.5)*8))*0.12*0.4+((((D13/100)*0.5+F13*0.5+G13*0.2+H13*0.8+I13*1+J13*3+K13*5+(D13/100)*0.3)*8+(L13*IF(O13="High",2,IF(O13="Medium",1,0.5)))*8+(M13*IF(P13="EC2 (Lift & Shift)",0.2,IF(P13="AWS QuickSight",1.5,IF(P13="Power BI",1,0.5))))*8+(10+(D13/100)*0.5)*8))*0.08*0.4 -> 547.14152 | AO13: =AI13+AL13+((M13*IF(P13="EC2 (Lift & Shift)",0.2,IF(P13="AWS QuickSight",1.5,IF(P13="Power BI",1,0.5))))*8)*0.2+((10+(D13/100)*0.5)*8)*0.2+AE13+((((D13/100)*0.5+F13*0.5+G13*0.2+H13*0.8+I13*1+J13*3+K13*5+(D13/100)*0.3)*8+(L13*IF(O13="High",2,IF(O13="Medium",1,0.5)))*8+(M13*IF(P13="EC2 (Lift & Shift)",0.2,IF(P13="AWS QuickSight",1.5,IF(P13="Power BI",1,0.5))))*8+(10+(D13/100)*0.5)*8))*0.28*0.2+((((D13/100)*0.5+F13*0.5+G13*0.2+H13*0.8+I13*1+J13*3+K13*5+(D13/100)*0.3)*8+(L13*IF(O13="High",2,IF(O13="Medium",1,0.5)))*8+(M13*IF(P13="EC2 (Lift & Shift)",0.2,IF(P13="AWS QuickSight",1.5,IF(P13="Power BI",1,0.5))))*8+(10+(D13/100)*0.5)*8))*0.12*0.2+((((D13/100)*0.5+F13*0.5+G13*0.2+H13*0.8+I13*1+J13*3+K13*5+(D13/100)*0.3)*8+(L13*IF(O13="High",2,IF(O13="Medium",1,0.5)))*8+(M13*IF(P13="EC2 (Lift & Shift)",0.2,IF(P13="AWS QuickSight",1.5,IF(P13="Power BI",1,0.5))))*8+(10+(D13/100)*0.5)*8))*0.08*0.2 -> 271.69576 | AP13: ='✏️ SME Input'!S13 -> 4 | AQ13: ='✏️ SME Input'!T13 -> 0 | AR13: ='✏️ SME Input'!U13 -> Transactional
B14: ='✏️ SME Input'!B14 -> Network Inventory DB | C14: =IF(D14>1000,"T3 Complex",IF(D14>500,"T2 Moderate","T1 Simple")) -> T2 Moderate | D14: ='✏️ SME Input'!D14 -> 560 | E14: ='✏️ SME Input'!E14 -> 130 | F14: ='✏️ SME Input'!F14 -> 95 | G14: ='✏️ SME Input'!G14 -> 48 | H14: ='✏️ SME Input'!H14 -> 10 | I14: ='✏️ SME Input'!I14 -> 9 | J14: ='✏️ SME Input'!J14 -> 2 | K14: ='✏️ SME Input'!K14 -> 1 | ... P14: ='✏️ SME Input'!P14 -> AWS QuickSight | Q14: ='✏️ SME Input'!C14 -> Wave 2 | R14: =((((D14/100)*0.5+F14*0.5+G14*0.2+H14*0.8+I14*1+J14*3+K14*5+(D14/100)*0.3)*8+(L14*IF(O14="High",2,IF(O14="Medium",1,0.5)))*8+(M14*IF(P14="EC2 (Lift & Shift)",0.2,IF(P14="AWS QuickSight",1.5,IF(P14="Power BI",1,0.5))))*8+(10+(D14/100)*0.5)*8))*0.08+(((D14/100)*0.5+F14*0.5+G14*0.2+H14*0.8+I14*1+J14*3+K14*5+(D14/100)*0.3)*8+(D14/100)*0.3*8)+((L14*IF(O14="High",2,IF(O14="Medium",1,0.5)))*8)+((M14*IF(P14="EC2 (Lift & Shift)",0.2,IF(P14="AWS QuickSight",1.5,IF(P14="Power BI",1,0.5))))*8)+((10+(D14/100)*0.5)*8)+((((D14/100)*0.5+F14*0.5+G14*0.2+H14*0.8+I14*1+J14*3+K14*5+(D14/100)*0.3)*8+(L14*IF(O14="High",2,IF(O14="Medium",1,0.5)))*8+(M14*IF(P14="EC2 (Lift & Shift)",0.2,IF(P14="AWS QuickSight",1.5,IF(P14="Power BI",1,0.5))))*8+(10+(D14/100)*0.5)*8))*0.28+((((D14/100)*0.5+F14*0.5+G14*0.2+H14*0.8+I14*1+J14*3+K14*5+(D14/100)*0.3)*8+(L14*IF(O14="High",2,IF(O14="Medium",1,0.5)))*8+(M14*IF(P14="EC2 (Lift & Shift)",0.2,IF(P14="AWS QuickSight",1.5,IF(P14="Power BI",1,0.5))))*8+(10+(D14/100)*0.5)*8))*0.12 -> 1746.5792 | S14: =((((D14/100)*0.5+F14*0.5+G14*0.2+H14*0.8+I14*1+J14*3+K14*5+(D14/100)*0.3)*8+(L14*IF(O14="High",2,IF(O14="Medium",1,0.5)))*8+(M14*IF(P14="EC2 (Lift & Shift)",0.2,IF(P14="AWS QuickSight",1.5,IF(P14="Power BI",1,0.5))))*8+(10+(D14/100)*0.5)*8)*0.08)*(1-'📊 Dashboard'!C10/100)+((((D14/100)*0.5+F14*0.5+G14*0.2+H14*0.8+I14*1+J14*3+K14*5+(D14/100)*0.3)*8+(D14/100)*0.3*8))*(1-'📊 Dashboard'!C10/100)+((L14*IF(O14="High",2,IF(O14="Medium",1,0.5)))*8)*(1-'📊 Dashboard'!C11/100)+((M14*IF(P14="EC2 (Lift & Shift)",0.2,IF(P14="AWS QuickSight",1.5,IF(P14="Power BI",1,0.5))))*8)*(1-'📊 Dashboard'!C12/100)+((10+(D14/100)*0.5)*8)*(1-'📊 Dashboard'!C10/100)+((((D14/100)*0.5+F14*0.5+G14*0.2+H14*0.8+I14*1+J14*3+K14*5+(D14/100)*0.3)*8+(L14*IF(O14="High",2,IF(O14="Medium",1,0.5)))*8+(M14*IF(P14="EC2 (Lift & Shift)",0.2,IF(P14="AWS QuickSight",1.5,IF(P14="Power BI",1,0.5))))*8+(10+(D14/100)*0.5)*8)*0.28)*(1-'📊 Dashboard'!C13/100)+((((D14/100)*0.5+F14*0.5+G14*0.2+H14*0.8+I14*1+J14*3+K14*5+(D14/100)*0.3)*8+(L14*IF(O14="High",2,IF(O14="Medium",1,0.5)))*8+(M14*IF(P14="EC2 (Lift & Shift)",0.2,IF(P14="AWS QuickSight",1.5,IF(P14="Power BI",1,0.5))))*8+(10+(D14/100)*0.5)*8)*0.12)*(1-'📊 Dashboard'!C10/100) -> 1282.5946 | T14: =S14*(1+'📊 Dashboard'!C14/100) -> 1474.9837 | U14: =(((D14/100)*0.5+F14*0.5+G14*0.2+H14*0.8+I14*1+J14*3+K14*5+(D14/100)*0.3)*8+(L14*IF(O14="High",2,IF(O14="Medium",1,0.5)))*8+(M14*IF(P14="EC2 (Lift & Shift)",0.2,IF(P14="AWS QuickSight",1.5,IF(P14="Power BI",1,0.5))))*8+(10+(D14/100)*0.5)*8)*0.08 -> 93.6832 | V14: =((D14/100)*0.5+F14*0.5+G14*0.2+H14*0.8+I14*1+J14*3+K14*5+(D14/100)*0.3)*8+(D14/100)*0.3*8 -> 730.08 | W14: =(L14*IF(O14="High",2,IF(O14="Medium",1,0.5)))*8 -> 160 | X14: =(M14*IF(P14="EC2 (Lift & Shift)",0.2,IF(P14="AWS QuickSight",1.5,IF(P14="Power BI",1,0.5))))*8 -> 192 | Y14: =(10+(D14/100)*0.5)*8 -> 102.4 | Z14: =(((D14/100)*0.5+F14*0.5+G14*0.2+H14*0.8+I14*1+J14*3+K14*5+(D14/100)*0.3)*8+(L14*IF(O14="High",2,IF(O14="Medium",1,0.5)))*8+(M14*IF(P14="EC2 (Lift & Shift)",0.2,IF(P14="AWS QuickSight",1.5,IF(P14="Power BI",1,0.5))))*8+(10+(D14/100)*0.5)*8)*0.28 -> 327.8912 | AA14: =(((D14/100)*0.5+F14*0.5+G14*0.2+H14*0.8+I14*1+J14*3+K14*5+(D14/100)*0.3)*8+(L14*IF(O14="High",2,IF(O14="Medium",1,0.5)))*8+(M14*IF(P14="EC2 (Lift & Shift)",0.2,IF(P14="AWS QuickSight",1.5,IF(P14="Power BI",1,0.5))))*8+(10+(D14/100)*0.5)*8)*0.12 -> 140.5248 | AB14: ='✏️ SME Input'!R14 -> 6 | AC14: =AB14*0.75 -> 4.5 | AD14: =AB14*0.75 -> 4.5 | AE14: =AB14*0.75 -> 4.5 | AF14: =AB14*2.25 -> 13.5 | AG14: =(((D14/100)*0.5+F14*0.5+G14*0.2+H14*0.8+I14*1+J14*3+K14*5+(D14/100)*0.3)*8)*0.4 -> 286.656 | AH14: =(((D14/100)*0.5+F14*0.5+G14*0.2+H14*0.8+I14*1+J14*3+K14*5+(D14/100)*0.3)*8)*0.4 -> 286.656 | AI14: =(((D14/100)*0.5+F14*0.5+G14*0.2+H14*0.8+I14*1+J14*3+K14*5+(D14/100)*0.3)*8)*0.2 -> 143.328 | AJ14: =((L14*IF(O14="High",2,IF(O14="Medium",1,0.5)))*8)*0.5 -> 80 | AK14: =((L14*IF(O14="High",2,IF(O14="Medium",1,0.5)))*8)*0.35 -> 56 | AL14: =((L14*IF(O14="High",2,IF(O14="Medium",1,0.5)))*8)*0.15 -> 24 | AM14: =AG14+AJ14+((M14*IF(P14="EC2 (Lift & Shift)",0.2,IF(P14="AWS QuickSight",1.5,IF(P14="Power BI",1,0.5))))*8)*0.4+((10+(D14/100)*0.5)*8)*0.4+AC14+((((D14/100)*0.5+F14*0.5+G14*0.2+H14*0.8+I14*1+J14*3+K14*5+(D14/100)*0.3)*8+(L14*IF(O14="High",2,IF(O14="Medium",1,0.5)))*8+(M14*IF(P14="EC2 (Lift & Shift)",0.2,IF(P14="AWS QuickSight",1.5,IF(P14="Power BI",1,0.5))))*8+(10+(D14/100)*0.5)*8))*0.28*0.4+((((D14/100)*0.5+F14*0.5+G14*0.2+H14*0.8+I14*1+J14*3+K14*5+(D14/100)*0.3)*8+(L14*IF(O14="High",2,IF(O14="Medium",1,0.5)))*8+(M14*IF(P14="EC2 (Lift & Shift)",0.2,IF(P14="AWS QuickSight",1.5,IF(P14="Power BI",1,0.5))))*8+(10+(D14/100)*0.5)*8))*0.12*0.4+((((D14/100)*0.5+F14*0.5+G14*0.2+H14*0.8+I14*1+J14*3+K14*5+(D14/100)*0.3)*8+(L14*IF(O14="High",2,IF(O14="Medium",1,0.5)))*8+(M14*IF(P14="EC2 (Lift & Shift)",0.2,IF(P14="AWS QuickSight",1.5,IF(P14="Power BI",1,0.5))))*8+(10+(D14/100)*0.5)*8))*0.08*0.4 -> 713.75568 | AN14: =AH14+AK14+((M14*IF(P14="EC2 (Lift & Shift)",0.2,IF(P14="AWS QuickSight",1.5,IF(P14="Power BI",1,0.5))))*8)*0.4+((10+(D14/100)*0.5)*8)*0.4+AD14+((((D14/100)*0.5+F14*0.5+G14*0.2+H14*0.8+I14*1+J14*3+K14*5+(D14/100)*0.3)*8+(L14*IF(O14="High",2,IF(O14="Medium",1,0.5)))*8+(M14*IF(P14="EC2 (Lift & Shift)",0.2,IF(P14="AWS QuickSight",1.5,IF(P14="Power BI",1,0.5))))*8+(10+(D14/100)*0.5)*8))*0.28*0.4+((((D14/100)*0.5+F14*0.5+G14*0.2+H14*0.8+I14*1+J14*3+K14*5+(D14/100)*0.3)*8+(L14*IF(O14="High",2,IF(O14="Medium",1,0.5)))*8+(M14*IF(P14="EC2 (Lift & Shift)",0.2,IF(P14="AWS QuickSight",1.5,IF(P14="Power BI",1,0.5))))*8+(10+(D14/100)*0.5)*8))*0.12*0.4+((((D14/100)*0.5+F14*0.5+G14*0.2+H14*0.8+I14*1+J14*3+K14*5+(D14/100)*0.3)*8+(L14*IF(O14="High",2,IF(O14="Medium",1,0.5)))*8+(M14*IF(P14="EC2 (Lift & Shift)",0.2,IF(P14="AWS QuickSight",1.5,IF(P14="Power BI",1,0.5))))*8+(10+(D14/100)*0.5)*8))*0.08*0.4 -> 689.75568 | AO14: =AI14+AL14+((M14*IF(P14="EC2 (Lift & Shift)",0.2,IF(P14="AWS QuickSight",1.5,IF(P14="Power BI",1,0.5))))*8)*0.2+((10+(D14/100)*0.5)*8)*0.2+AE14+((((D14/100)*0.5+F14*0.5+G14*0.2+H14*0.8+I14*1+J14*3+K14*5+(D14/100)*0.3)*8+(L14*IF(O14="High",2,IF(O14="Medium",1,0.5)))*8+(M14*IF(P14="EC2 (Lift & Shift)",0.2,IF(P14="AWS QuickSight",1.5,IF(P14="Power BI",1,0.5))))*8+(10+(D14/100)*0.5)*8))*0.28*0.2+((((D14/100)*0.5+F14*0.5+G14*0.2+H14*0.8+I14*1+J14*3+K14*5+(D14/100)*0.3)*8+(L14*IF(O14="High",2,IF(O14="Medium",1,0.5)))*8+(M14*IF(P14="EC2 (Lift & Shift)",0.2,IF(P14="AWS QuickSight",1.5,IF(P14="Power BI",1,0.5))))*8+(10+(D14/100)*0.5)*8))*0.12*0.2+((((D14/100)*0.5+F14*0.5+G14*0.2+H14*0.8+I14*1+J14*3+K14*5+(D14/100)*0.3)*8+(L14*IF(O14="High",2,IF(O14="Medium",1,0.5)))*8+(M14*IF(P14="EC2 (Lift & Shift)",0.2,IF(P14="AWS QuickSight",1.5,IF(P14="Power BI",1,0.5))))*8+(10+(D14/100)*0.5)*8))*0.08*0.2 -> 343.12784 | AP14: ='✏️ SME Input'!S14 -> 5 | AQ14: ='✏️ SME Input'!T14 -> 0 | AR14: ='✏️ SME Input'!U14 -> Transactional
